Workbook

Sheet Nasıl Kullanılır
A1: 9. Sınıf Deneme Takip Dosyası
A3: 1. Ayarlar | B3: Önce Ayarlar sayfasında derslerin adını, her dersin soru sayısını ve hedef netini kendi denemene göre düzelt. Yanlış katsayısı varsayılan 4 (4 yanlış 1 doğruyu götürür).
A4: 2. Deneme Girişi | B4: Her denemeden sonra bir satır doldur: tarih, deneme adı, her ders için Doğru (D) ve Yanlış (Y). 'Soru' hücresine sadece o denemede o dersin soru sayısı farklıysa yaz; boş bırakırsan Ayarlar'daki sayı kullanılır. Bir ders o denemede hiç yoksa D ve Y'yi boş bırak. Dersi tamamen boş bıraktıysan D=0, Y=0 yaz. D+Y soru sayısını geçerse hücre kırmızı olur.
A5: 3. Konu Takibi | B5: Yanlış/boş yaptığın her soruyu konu adıyla yaz, hata nedenini listeden seç. Aynı konuda 2. hata sarı, 3. ve sonrası kırmızı yanar. Konuyu tekrar çalışınca 'Evet' seç.
A6: 4. Analiz | B6: Soru sayıları denemeden denemeye değişebildiği için karşılaştırmalar Başarı % (net ÷ soru) üzerinden yapılır. Hiçbir şey yazmadan özet kartları, ders bazında başarı yüzdesini, hedefe kalan neti, hata nedenlerini ve grafikleri görürsün. Ders seç kutusundan tek bir dersin gelişimine bak.
A7: Tahmini TYT | B7: Deneme Girişi'nin sonunda ve Analiz'de yaklaşık bir TYT puanı görürsün. Her ders bir TYT testine sayılır (Edebiyat→Türkçe, Tarih/Coğrafya/Din→Sosyal, Fizik/Kimya/Biyoloji→Fen). O testteki başarı yüzden TYT soru sayısıyla çarpılır, katsayılarla puana çevrilir. Kaba bir tahmindir; eşleme ve katsayılar Ayarlar'da.
A8: Renkler | B8: Krem renkli hücreler = senin dolduracağın yerler. Mavi yazı = elle girilen veri. Siyah/kalın = otomatik formül (değiştirme).
A9: Örnek satır | B9: Deneme Girişi ve Konu Takibi'nin ilk satırında örnek veri var — formatı gösteriyor. Kendi verini girmeden önce silebilirsin.
A10: İpucu | B10: Konu Takibi'nde başlıklardaki filtre oklarıyla 'Ders = Matematik' ve 'Tekrar Çalışıldı mı? = Hayır' seçersen, çalışman gereken soruların listesi çıkar.
A12: Örnek giriş hücresi

Sheet Deneme Girişi
A1: Deneme Sonuçları
A2: Her deneme için bir satır: Doğru (D) ve Yanlış (Y) gir. 'Soru' hücresini SADECE o denemede soru sayısı farklıysa doldur; boşsa Ayarlar'daki sayı kullanılır.
A3: No | B3: Tarih | C3: Deneme / Yayın | D3: =Ayarlar!A4 | H3: =Ayarlar!A5 | L3: =Ayarlar!A6 | P3: =Ayarlar!A7 | T3: =Ayarlar!A8 | X3: =Ayarlar!A9 | AB3: =Ayarlar!A10 | AF3: =Ayarlar!A11 | AJ3: TOPLAM | AQ3: TAHMİNİ TYT (yaklaşık)
D4: D | E4: Y | F4: Soru | G4: Net | H4: D | I4: Y | J4: Soru | K4: Net | L4: D | M4: Y | N4: Soru | O4: Net | P4: D | Q4: Y | R4: Soru | S4: Net | T4: D | U4: Y | V4: Soru | W4: Net | X4: D | Y4: Y | Z4: Soru | AA4: Net | AB4: D | AC4: Y | AD4: Soru | AE4: Net | AF4: D | AG4: Y | AH4: Soru | AI4: Net | AJ4: D | AK4: Y | AL4: Soru | AM4: Boş | AN4: Net | AO4: Başarı % | AP4: Değişim | AQ4: =Ayarlar!E21&" net" | AR4: =Ayarlar!E22&" net" | AS4: =Ayarlar!E23&" net" | AT4: =Ayarlar!E24&" net" | AU4: Puan
A5: 1 | B5: 46285 | C5: Örnek Yayın – Deneme 1 (silebilirsin) | D5: 9 | E5: 2 | G5: =IF(AND(D5="",E5=""),"",D5-IF(Ayarlar!$B$16>0,E5/Ayarlar!$B$16,0)) | H5: 10 | I5: 0 | K5: =IF(AND(H5="",I5=""),"",H5-IF(Ayarlar!$B$16>0,I5/Ayarlar!$B$16,0)) | L5: 3 | M5: 1 | O5: =IF(AND(L5="",M5=""),"",L5-IF(Ayarlar!$B$16>0,M5/Ayarlar!$B$16,0)) | P5: 5 | Q5: 0 | S5: =IF(AND(P5="",Q5=""),"",P5-IF(Ayarlar!$B$16>0,Q5/Ayarlar!$B$16,0)) | T5: 7 | U5: 1 | W5: =IF(AND(T5="",U5=""),"",T5-IF(Ayarlar!$B$16>0,U5/Ayarlar!$B$16,0)) | X5: 3 | Y5: 6 | AA5: =IF(AND(X5="",Y5=""),"",X5-IF(Ayarlar!$B$16>0,Y5/Ayarlar!$B$16,0)) | AB5: 5 | AC5: 1 | AE5: =IF(AND(AB5="",AC5=""),"",AB5-IF(Ayarlar!$B$16>0,AC5/Ayarlar!$B$16,0)) | AF5: 3 | AG5: 6 | AI5: =IF(AND(AF5="",AG5=""),"",AF5-IF(Ayarlar!$B$16>0,AG5/Ayarlar!$B$16,0)) | AJ5: =IF(COUNT(D5,E5,H5,I5,L5,M5,P5,Q5,T5,U5,X5,Y5,AB5,AC5,AF5,AG5)=0,"",D5+H5+L5+P5+T5+X5+AB5+AF5) | AK5: =IF(COUNT(D5,E5,H5,I5,L5,M5,P5,Q5,T5,U5,X5,Y5,AB5,AC5,AF5,AG5)=0,"",E5+I5+M5+Q5+U5+Y5+AC5+AG5) | AL5: =IF(COUNT(D5,E5,H5,I5,L5,M5,P5,Q5,T5,U5,X5,Y5,AB5,AC5,AF5,AG5)=0,"",IF(ISNUMBER(G5),IF(F5="",Ayarlar!$B$4,F5),0)+IF(ISNUMBER(K5),IF(J5="",Ayarlar!$B$5,J5),0)+IF(ISNUMBER(O5),IF(N5="",Ayarlar!$B$6,N5),0)+IF(ISNUMBER(S5),IF(R5="",Ayarlar!$B$7,R5),0)+IF(ISNUMBER(W5),IF(V5="",Ayarlar!$B$8,V5),0)+IF(ISNUMBER(AA5),IF(Z5="",Ayarlar!$B$9,Z5),0)+IF(ISNUMBER(AE5),IF(AD5="",Ayarlar!$B$10,AD5),0)+IF(ISNUMBER(AI5),IF(AH5="",Ayarlar!$B$11,AH5),0)) | AM5: =IF(COUNT(D5,E5,H5,I5,L5,M5,P5,Q5,T5,U5,X5,Y5,AB5,AC5,AF5,AG5)=0,"",AL5-AJ5-AK5) | AN5: =IF(COUNT(D5,E5,H5,I5,L5,M5,P5,Q5,T5,U5,X5,Y5,AB5,AC5,AF5,AG5)=0,"",SUM(G5,K5,O5,S5,W5,AA5,AE5,AI5)) | AO5: =IF(OR(COUNT(D5,E5,H5,I5,L5,M5,P5,Q5,T5,U5,X5,Y5,AB5,AC5,AF5,AG5)=0,N(AL5)=0),"",AN5/AL5) | AQ5: =IFERROR((IF(Ayarlar!$B$21=Ayarlar!$E$21,N(G5),0)+IF(Ayarlar!$B$22=Ayarlar!$E$21,N(K5),0)+IF(Ayarlar!$B$23=Ayarlar!$E$21,N(O5),0)+IF(Ayarlar!$B$24=Ayarlar!$E$21,N(S5),0)+IF(Ayarlar!$B$25=Ayarlar!$E$21,N(W5),0)+IF(Ayarlar!$B$26=Ayarlar!$E$21,N(AA5),0)+IF(Ayarlar!$B$27=Ayarlar!$E$21,N(AE5),0)+IF(Ayarlar!$B$28=Ayarlar!$E$21,N(AI5),0))/(IF(AND(Ayarlar!$B$21=Ayarlar!$E$21,ISNUMBER(G5)),IF(F5="",Ayarlar!$B$4,F5),0)+IF(AND(Ayarlar!$B$22=Ayarlar!$E$21,ISNUMBER(K5)),IF(J5="",Ayarlar!$B$5,J5),0)+IF(AND(Ayarlar!$B$23=Ayarlar!$E$21,ISNUMBER(O5)),IF(N5="",Ayarlar!$B$6,N5),0)+IF(AND(Ayarlar!$B$24=Ayarlar!$E$21,ISNUMBER(S5)),IF(R5="",Ayarlar!$B$7,R5),0)+IF(AND(Ayarlar!$B$25=Ayarlar!$E$21,ISNUMBER(W5)),IF(V5="",Ayarlar!$B$8,V5),0)+IF(AND(Ayarlar!$B$26=Ayarlar!$E$21,ISNUMBER(AA5)),IF(Z5="",Ayarlar!$B$9,Z5),0)+IF(AND(Ayarlar!$B$27=Ayarlar!$E$21,ISNUMBER(AE5)),IF(AD5="",Ayarlar!$B$10,AD5),0)+IF(AND(Ayarlar!$B$28=Ayarlar!$E$21,ISNUMBER(AI5)),IF(AH5="",Ayarlar!$B$11,AH5),0))*Ayarlar!$F$21,"") | AR5: =IFERROR((IF(Ayarlar!$B$21=Ayarlar!$E$22,N(G5),0)+IF(Ayarlar!$B$22=Ayarlar!$E$22,N(K5),0)+IF(Ayarlar!$B$23=Ayarlar!$E$22,N(O5),0)+IF(Ayarlar!$B$24=Ayarlar!$E$22,N(S5),0)+IF(Ayarlar!$B$25=Ayarlar!$E$22,N(W5),0)+IF(Ayarlar!$B$26=Ayarlar!$E$22,N(AA5),0)+IF(Ayarlar!$B$27=Ayarlar!$E$22,N(AE5),0)+IF(Ayarlar!$B$28=Ayarlar!$E$22,N(AI5),0))/(IF(AND(Ayarlar!$B$21=Ayarlar!$E$22,ISNUMBER(G5)),IF(F5="",Ayarlar!$B$4,F5),0)+IF(AND(Ayarlar!$B$22=Ayarlar!$E$22,ISNUMBER(K5)),IF(J5="",Ayarlar!$B$5,J5),0)+IF(AND(Ayarlar!$B$23=Ayarlar!$E$22,ISNUMBER(O5)),IF(N5="",Ayarlar!$B$6,N5),0)+IF(AND(Ayarlar!$B$24=Ayarlar!$E$22,ISNUMBER(S5)),IF(R5="",Ayarlar!$B$7,R5),0)+IF(AND(Ayarlar!$B$25=Ayarlar!$E$22,ISNUMBER(W5)),IF(V5="",Ayarlar!$B$8,V5),0)+IF(AND(Ayarlar!$B$26=Ayarlar!$E$22,ISNUMBER(AA5)),IF(Z5="",Ayarlar!$B$9,Z5),0)+IF(AND(Ayarlar!$B$27=Ayarlar!$E$22,ISNUMBER(AE5)),IF(AD5="",Ayarlar!$B$10,AD5),0)+IF(AND(Ayarlar!$B$28=Ayarlar!$E$22,ISNUMBER(AI5)),IF(AH5="",Ayarlar!$B$11,AH5),0))*Ayarlar!$F$22,"") | AS5: =IFERROR((IF(Ayarlar!$B$21=Ayarlar!$E$23,N(G5),0)+IF(Ayarlar!$B$22=Ayarlar!$E$23,N(K5),0)+IF(Ayarlar!$B$23=Ayarlar!$E$23,N(O5),0)+IF(Ayarlar!$B$24=Ayarlar!$E$23,N(S5),0)+IF(Ayarlar!$B$25=Ayarlar!$E$23,N(W5),0)+IF(Ayarlar!$B$26=Ayarlar!$E$23,N(AA5),0)+IF(Ayarlar!$B$27=Ayarlar!$E$23,N(AE5),0)+IF(Ayarlar!$B$28=Ayarlar!$E$23,N(AI5),0))/(IF(AND(Ayarlar!$B$21=Ayarlar!$E$23,ISNUMBER(G5)),IF(F5="",Ayarlar!$B$4,F5),0)+IF(AND(Ayarlar!$B$22=Ayarlar!$E$23,ISNUMBER(K5)),IF(J5="",Ayarlar!$B$5,J5),0)+IF(AND(Ayarlar!$B$23=Ayarlar!$E$23,ISNUMBER(O5)),IF(N5="",Ayarlar!$B$6,N5),0)+IF(AND(Ayarlar!$B$24=Ayarlar!$E$23,ISNUMBER(S5)),IF(R5="",Ayarlar!$B$7,R5),0)+IF(AND(Ayarlar!$B$25=Ayarlar!$E$23,ISNUMBER(W5)),IF(V5="",Ayarlar!$B$8,V5),0)+IF(AND(Ayarlar!$B$26=Ayarlar!$E$23,ISNUMBER(AA5)),IF(Z5="",Ayarlar!$B$9,Z5),0)+IF(AND(Ayarlar!$B$27=Ayarlar!$E$23,ISNUMBER(AE5)),IF(AD5="",Ayarlar!$B$10,AD5),0)+IF(AND(Ayarlar!$B$28=Ayarlar!$E$23,ISNUMBER(AI5)),IF(AH5="",Ayarlar!$B$11,AH5),0))*Ayarlar!$F$23,"") | AT5: =IFERROR((IF(Ayarlar!$B$21=Ayarlar!$E$24,N(G5),0)+IF(Ayarlar!$B$22=Ayarlar!$E$24,N(K5),0)+IF(Ayarlar!$B$23=Ayarlar!$E$24,N(O5),0)+IF(Ayarlar!$B$24=Ayarlar!$E$24,N(S5),0)+IF(Ayarlar!$B$25=Ayarlar!$E$24,N(W5),0)+IF(Ayarlar!$B$26=Ayarlar!$E$24,N(AA5),0)+IF(Ayarlar!$B$27=Ayarlar!$E$24,N(AE5),0)+IF(Ayarlar!$B$28=Ayarlar!$E$24,N(AI5),0))/(IF(AND(Ayarlar!$B$21=Ayarlar!$E$24,ISNUMBER(G5)),IF(F5="",Ayarlar!$B$4,F5),0)+IF(AND(Ayarlar!$B$22=Ayarlar!$E$24,ISNUMBER(K5)),IF(J5="",Ayarlar!$B$5,J5),0)+IF(AND(Ayarlar!$B$23=Ayarlar!$E$24,ISNUMBER(O5)),IF(N5="",Ayarlar!$B$6,N5),0)+IF(AND(Ayarlar!$B$24=Ayarlar!$E$24,ISNUMBER(S5)),IF(R5="",Ayarlar!$B$7,R5),0)+IF(AND(Ayarlar!$B$25=Ayarlar!$E$24,ISNUMBER(W5)),IF(V5="",Ayarlar!$B$8,V5),0)+IF(AND(Ayarlar!$B$26=Ayarlar!$E$24,ISNUMBER(AA5)),IF(Z5="",Ayarlar!$B$9,Z5),0)+IF(AND(Ayarlar!$B$27=Ayarlar!$E$24,ISNUMBER(AE5)),IF(AD5="",Ayarlar!$B$10,AD5),0)+IF(AND(Ayarlar!$B$28=Ayarlar!$E$24,ISNUMBER(AI5)),IF(AH5="",Ayarlar!$B$11,AH5),0))*Ayarlar!$F$24,"") | AU5: =IF(COUNT(AQ5,AR5,AS5,AT5)<4,"",Ayarlar!$F$25+AQ5*Ayarlar!$G$21+AR5*Ayarlar!$G$22+AS5*Ayarlar!$G$23+AT5*Ayarlar!$G$24)
A6: 2 | G6: =IF(AND(D6="",E6=""),"",D6-IF(Ayarlar!$B$16>0,E6/Ayarlar!$B$16,0)) | K6: =IF(AND(H6="",I6=""),"",H6-IF(Ayarlar!$B$16>0,I6/Ayarlar!$B$16,0)) | O6: =IF(AND(L6="",M6=""),"",L6-IF(Ayarlar!$B$16>0,M6/Ayarlar!$B$16,0)) | S6: =IF(AND(P6="",Q6=""),"",P6-IF(Ayarlar!$B$16>0,Q6/Ayarlar!$B$16,0)) | W6: =IF(AND(T6="",U6=""),"",T6-IF(Ayarlar!$B$16>0,U6/Ayarlar!$B$16,0)) | AA6: =IF(AND(X6="",Y6=""),"",X6-IF(Ayarlar!$B$16>0,Y6/Ayarlar!$B$16,0)) | AE6: =IF(AND(AB6="",AC6=""),"",AB6-IF(Ayarlar!$B$16>0,AC6/Ayarlar!$B$16,0)) | AI6: =IF(AND(AF6="",AG6=""),"",AF6-IF(Ayarlar!$B$16>0,AG6/Ayarlar!$B$16,0)) | AJ6: =IF(COUNT(D6,E6,H6,I6,L6,M6,P6,Q6,T6,U6,X6,Y6,AB6,AC6,AF6,AG6)=0,"",D6+H6+L6+P6+T6+X6+AB6+AF6) | AK6: =IF(COUNT(D6,E6,H6,I6,L6,M6,P6,Q6,T6,U6,X6,Y6,AB6,AC6,AF6,AG6)=0,"",E6+I6+M6+Q6+U6+Y6+AC6+AG6) | AL6: =IF(COUNT(D6,E6,H6,I6,L6,M6,P6,Q6,T6,U6,X6,Y6,AB6,AC6,AF6,AG6)=0,"",IF(ISNUMBER(G6),IF(F6="",Ayarlar!$B$4,F6),0)+IF(ISNUMBER(K6),IF(J6="",Ayarlar!$B$5,J6),0)+IF(ISNUMBER(O6),IF(N6="",Ayarlar!$B$6,N6),0)+IF(ISNUMBER(S6),IF(R6="",Ayarlar!$B$7,R6),0)+IF(ISNUMBER(W6),IF(V6="",Ayarlar!$B$8,V6),0)+IF(ISNUMBER(AA6),IF(Z6="",Ayarlar!$B$9,Z6),0)+IF(ISNUMBER(AE6),IF(AD6="",Ayarlar!$B$10,AD6),0)+IF(ISNUMBER(AI6),IF(AH6="",Ayarlar!$B$11,AH6),0)) | AM6: =IF(COUNT(D6,E6,H6,I6,L6,M6,P6,Q6,T6,U6,X6,Y6,AB6,AC6,AF6,AG6)=0,"",AL6-AJ6-AK6) | AN6: =IF(COUNT(D6,E6,H6,I6,L6,M6,P6,Q6,T6,U6,X6,Y6,AB6,AC6,AF6,AG6)=0,"",SUM(G6,K6,O6,S6,W6,AA6,AE6,AI6)) | AO6: =IF(OR(COUNT(D6,E6,H6,I6,L6,M6,P6,Q6,T6,U6,X6,Y6,AB6,AC6,AF6,AG6)=0,N(AL6)=0),"",AN6/AL6) | AP6: =IF(OR(AO6="",AO5=""),"",AO6-AO5) | AQ6: =IFERROR((IF(Ayarlar!$B$21=Ayarlar!$E$21,N(G6),0)+IF(Ayarlar!$B$22=Ayarlar!$E$21,N(K6),0)+IF(Ayarlar!$B$23=Ayarlar!$E$21,N(O6),0)+IF(Ayarlar!$B$24=Ayarlar!$E$21,N(S6),0)+IF(Ayarlar!$B$25=Ayarlar!$E$21,N(W6),0)+IF(Ayarlar!$B$26=Ayarlar!$E$21,N(AA6),0)+IF(Ayarlar!$B$27=Ayarlar!$E$21,N(AE6),0)+IF(Ayarlar!$B$28=Ayarlar!$E$21,N(AI6),0))/(IF(AND(Ayarlar!$B$21=Ayarlar!$E$21,ISNUMBER(G6)),IF(F6="",Ayarlar!$B$4,F6),0)+IF(AND(Ayarlar!$B$22=Ayarlar!$E$21,ISNUMBER(K6)),IF(J6="",Ayarlar!$B$5,J6),0)+IF(AND(Ayarlar!$B$23=Ayarlar!$E$21,ISNUMBER(O6)),IF(N6="",Ayarlar!$B$6,N6),0)+IF(AND(Ayarlar!$B$24=Ayarlar!$E$21,ISNUMBER(S6)),IF(R6="",Ayarlar!$B$7,R6),0)+IF(AND(Ayarlar!$B$25=Ayarlar!$E$21,ISNUMBER(W6)),IF(V6="",Ayarlar!$B$8,V6),0)+IF(AND(Ayarlar!$B$26=Ayarlar!$E$21,ISNUMBER(AA6)),IF(Z6="",Ayarlar!$B$9,Z6),0)+IF(AND(Ayarlar!$B$27=Ayarlar!$E$21,ISNUMBER(AE6)),IF(AD6="",Ayarlar!$B$10,AD6),0)+IF(AND(Ayarlar!$B$28=Ayarlar!$E$21,ISNUMBER(AI6)),IF(AH6="",Ayarlar!$B$11,AH6),0))*Ayarlar!$F$21,"") | AR6: =IFERROR((IF(Ayarlar!$B$21=Ayarlar!$E$22,N(G6),0)+IF(Ayarlar!$B$22=Ayarlar!$E$22,N(K6),0)+IF(Ayarlar!$B$23=Ayarlar!$E$22,N(O6),0)+IF(Ayarlar!$B$24=Ayarlar!$E$22,N(S6),0)+IF(Ayarlar!$B$25=Ayarlar!$E$22,N(W6),0)+IF(Ayarlar!$B$26=Ayarlar!$E$22,N(AA6),0)+IF(Ayarlar!$B$27=Ayarlar!$E$22,N(AE6),0)+IF(Ayarlar!$B$28=Ayarlar!$E$22,N(AI6),0))/(IF(AND(Ayarlar!$B$21=Ayarlar!$E$22,ISNUMBER(G6)),IF(F6="",Ayarlar!$B$4,F6),0)+IF(AND(Ayarlar!$B$22=Ayarlar!$E$22,ISNUMBER(K6)),IF(J6="",Ayarlar!$B$5,J6),0)+IF(AND(Ayarlar!$B$23=Ayarlar!$E$22,ISNUMBER(O6)),IF(N6="",Ayarlar!$B$6,N6),0)+IF(AND(Ayarlar!$B$24=Ayarlar!$E$22,ISNUMBER(S6)),IF(R6="",Ayarlar!$B$7,R6),0)+IF(AND(Ayarlar!$B$25=Ayarlar!$E$22,ISNUMBER(W6)),IF(V6="",Ayarlar!$B$8,V6),0)+IF(AND(Ayarlar!$B$26=Ayarlar!$E$22,ISNUMBER(AA6)),IF(Z6="",Ayarlar!$B$9,Z6),0)+IF(AND(Ayarlar!$B$27=Ayarlar!$E$22,ISNUMBER(AE6)),IF(AD6="",Ayarlar!$B$10,AD6),0)+IF(AND(Ayarlar!$B$28=Ayarlar!$E$22,ISNUMBER(AI6)),IF(AH6="",Ayarlar!$B$11,AH6),0))*Ayarlar!$F$22,"") | AS6: =IFERROR((IF(Ayarlar!$B$21=Ayarlar!$E$23,N(G6),0)+IF(Ayarlar!$B$22=Ayarlar!$E$23,N(K6),0)+IF(Ayarlar!$B$23=Ayarlar!$E$23,N(O6),0)+IF(Ayarlar!$B$24=Ayarlar!$E$23,N(S6),0)+IF(Ayarlar!$B$25=Ayarlar!$E$23,N(W6),0)+IF(Ayarlar!$B$26=Ayarlar!$E$23,N(AA6),0)+IF(Ayarlar!$B$27=Ayarlar!$E$23,N(AE6),0)+IF(Ayarlar!$B$28=Ayarlar!$E$23,N(AI6),0))/(IF(AND(Ayarlar!$B$21=Ayarlar!$E$23,ISNUMBER(G6)),IF(F6="",Ayarlar!$B$4,F6),0)+IF(AND(Ayarlar!$B$22=Ayarlar!$E$23,ISNUMBER(K6)),IF(J6="",Ayarlar!$B$5,J6),0)+IF(AND(Ayarlar!$B$23=Ayarlar!$E$23,ISNUMBER(O6)),IF(N6="",Ayarlar!$B$6,N6),0)+IF(AND(Ayarlar!$B$24=Ayarlar!$E$23,ISNUMBER(S6)),IF(R6="",Ayarlar!$B$7,R6),0)+IF(AND(Ayarlar!$B$25=Ayarlar!$E$23,ISNUMBER(W6)),IF(V6="",Ayarlar!$B$8,V6),0)+IF(AND(Ayarlar!$B$26=Ayarlar!$E$23,ISNUMBER(AA6)),IF(Z6="",Ayarlar!$B$9,Z6),0)+IF(AND(Ayarlar!$B$27=Ayarlar!$E$23,ISNUMBER(AE6)),IF(AD6="",Ayarlar!$B$10,AD6),0)+IF(AND(Ayarlar!$B$28=Ayarlar!$E$23,ISNUMBER(AI6)),IF(AH6="",Ayarlar!$B$11,AH6),0))*Ayarlar!$F$23,"") | AT6: =IFERROR((IF(Ayarlar!$B$21=Ayarlar!$E$24,N(G6),0)+IF(Ayarlar!$B$22=Ayarlar!$E$24,N(K6),0)+IF(Ayarlar!$B$23=Ayarlar!$E$24,N(O6),0)+IF(Ayarlar!$B$24=Ayarlar!$E$24,N(S6),0)+IF(Ayarlar!$B$25=Ayarlar!$E$24,N(W6),0)+IF(Ayarlar!$B$26=Ayarlar!$E$24,N(AA6),0)+IF(Ayarlar!$B$27=Ayarlar!$E$24,N(AE6),0)+IF(Ayarlar!$B$28=Ayarlar!$E$24,N(AI6),0))/(IF(AND(Ayarlar!$B$21=Ayarlar!$E$24,ISNUMBER(G6)),IF(F6="",Ayarlar!$B$4,F6),0)+IF(AND(Ayarlar!$B$22=Ayarlar!$E$24,ISNUMBER(K6)),IF(J6="",Ayarlar!$B$5,J6),0)+IF(AND(Ayarlar!$B$23=Ayarlar!$E$24,ISNUMBER(O6)),IF(N6="",Ayarlar!$B$6,N6),0)+IF(AND(Ayarlar!$B$24=Ayarlar!$E$24,ISNUMBER(S6)),IF(R6="",Ayarlar!$B$7,R6),0)+IF(AND(Ayarlar!$B$25=Ayarlar!$E$24,ISNUMBER(W6)),IF(V6="",Ayarlar!$B$8,V6),0)+IF(AND(Ayarlar!$B$26=Ayarlar!$E$24,ISNUMBER(AA6)),IF(Z6="",Ayarlar!$B$9,Z6),0)+IF(AND(Ayarlar!$B$27=Ayarlar!$E$24,ISNUMBER(AE6)),IF(AD6="",Ayarlar!$B$10,AD6),0)+IF(AND(Ayarlar!$B$28=Ayarlar!$E$24,ISNUMBER(AI6)),IF(AH6="",Ayarlar!$B$11,AH6),0))*Ayarlar!$F$24,"") | AU6: =IF(COUNT(AQ6,AR6,AS6,AT6)<4,"",Ayarlar!$F$25+AQ6*Ayarlar!$G$21+AR6*Ayarlar!$G$22+AS6*Ayarlar!$G$23+AT6*Ayarlar!$G$24)
A7: 3 | G7: =IF(AND(D7="",E7=""),"",D7-IF(Ayarlar!$B$16>0,E7/Ayarlar!$B$16,0)) | K7: =IF(AND(H7="",I7=""),"",H7-IF(Ayarlar!$B$16>0,I7/Ayarlar!$B$16,0)) | O7: =IF(AND(L7="",M7=""),"",L7-IF(Ayarlar!$B$16>0,M7/Ayarlar!$B$16,0)) | S7: =IF(AND(P7="",Q7=""),"",P7-IF(Ayarlar!$B$16>0,Q7/Ayarlar!$B$16,0)) | W7: =IF(AND(T7="",U7=""),"",T7-IF(Ayarlar!$B$16>0,U7/Ayarlar!$B$16,0)) | AA7: =IF(AND(X7="",Y7=""),"",X7-IF(Ayarlar!$B$16>0,Y7/Ayarlar!$B$16,0)) | AE7: =IF(AND(AB7="",AC7=""),"",AB7-IF(Ayarlar!$B$16>0,AC7/Ayarlar!$B$16,0)) | AI7: =IF(AND(AF7="",AG7=""),"",AF7-IF(Ayarlar!$B$16>0,AG7/Ayarlar!$B$16,0)) | AJ7: =IF(COUNT(D7,E7,H7,I7,L7,M7,P7,Q7,T7,U7,X7,Y7,AB7,AC7,AF7,AG7)=0,"",D7+H7+L7+P7+T7+X7+AB7+AF7) | AK7: =IF(COUNT(D7,E7,H7,I7,L7,M7,P7,Q7,T7,U7,X7,Y7,AB7,AC7,AF7,AG7)=0,"",E7+I7+M7+Q7+U7+Y7+AC7+AG7) | AL7: =IF(COUNT(D7,E7,H7,I7,L7,M7,P7,Q7,T7,U7,X7,Y7,AB7,AC7,AF7,AG7)=0,"",IF(ISNUMBER(G7),IF(F7="",Ayarlar!$B$4,F7),0)+IF(ISNUMBER(K7),IF(J7="",Ayarlar!$B$5,J7),0)+IF(ISNUMBER(O7),IF(N7="",Ayarlar!$B$6,N7),0)+IF(ISNUMBER(S7),IF(R7="",Ayarlar!$B$7,R7),0)+IF(ISNUMBER(W7),IF(V7="",Ayarlar!$B$8,V7),0)+IF(ISNUMBER(AA7),IF(Z7="",Ayarlar!$B$9,Z7),0)+IF(ISNUMBER(AE7),IF(AD7="",Ayarlar!$B$10,AD7),0)+IF(ISNUMBER(AI7),IF(AH7="",Ayarlar!$B$11,AH7),0)) | AM7: =IF(COUNT(D7,E7,H7,I7,L7,M7,P7,Q7,T7,U7,X7,Y7,AB7,AC7,AF7,AG7)=0,"",AL7-AJ7-AK7) | AN7: =IF(COUNT(D7,E7,H7,I7,L7,M7,P7,Q7,T7,U7,X7,Y7,AB7,AC7,AF7,AG7)=0,"",SUM(G7,K7,O7,S7,W7,AA7,AE7,AI7)) | AO7: =IF(OR(COUNT(D7,E7,H7,I7,L7,M7,P7,Q7,T7,U7,X7,Y7,AB7,AC7,AF7,AG7)=0,N(AL7)=0),"",AN7/AL7) | AP7: =IF(OR(AO7="",AO6=""),"",AO7-AO6) | AQ7: =IFERROR((IF(Ayarlar!$B$21=Ayarlar!$E$21,N(G7),0)+IF(Ayarlar!$B$22=Ayarlar!$E$21,N(K7),0)+IF(Ayarlar!$B$23=Ayarlar!$E$21,N(O7),0)+IF(Ayarlar!$B$24=Ayarlar!$E$21,N(S7),0)+IF(Ayarlar!$B$25=Ayarlar!$E$21,N(W7),0)+IF(Ayarlar!$B$26=Ayarlar!$E$21,N(AA7),0)+IF(Ayarlar!$B$27=Ayarlar!$E$21,N(AE7),0)+IF(Ayarlar!$B$28=Ayarlar!$E$21,N(AI7),0))/(IF(AND(Ayarlar!$B$21=Ayarlar!$E$21,ISNUMBER(G7)),IF(F7="",Ayarlar!$B$4,F7),0)+IF(AND(Ayarlar!$B$22=Ayarlar!$E$21,ISNUMBER(K7)),IF(J7="",Ayarlar!$B$5,J7),0)+IF(AND(Ayarlar!$B$23=Ayarlar!$E$21,ISNUMBER(O7)),IF(N7="",Ayarlar!$B$6,N7),0)+IF(AND(Ayarlar!$B$24=Ayarlar!$E$21,ISNUMBER(S7)),IF(R7="",Ayarlar!$B$7,R7),0)+IF(AND(Ayarlar!$B$25=Ayarlar!$E$21,ISNUMBER(W7)),IF(V7="",Ayarlar!$B$8,V7),0)+IF(AND(Ayarlar!$B$26=Ayarlar!$E$21,ISNUMBER(AA7)),IF(Z7="",Ayarlar!$B$9,Z7),0)+IF(AND(Ayarlar!$B$27=Ayarlar!$E$21,ISNUMBER(AE7)),IF(AD7="",Ayarlar!$B$10,AD7),0)+IF(AND(Ayarlar!$B$28=Ayarlar!$E$21,ISNUMBER(AI7)),IF(AH7="",Ayarlar!$B$11,AH7),0))*Ayarlar!$F$21,"") | AR7: =IFERROR((IF(Ayarlar!$B$21=Ayarlar!$E$22,N(G7),0)+IF(Ayarlar!$B$22=Ayarlar!$E$22,N(K7),0)+IF(Ayarlar!$B$23=Ayarlar!$E$22,N(O7),0)+IF(Ayarlar!$B$24=Ayarlar!$E$22,N(S7),0)+IF(Ayarlar!$B$25=Ayarlar!$E$22,N(W7),0)+IF(Ayarlar!$B$26=Ayarlar!$E$22,N(AA7),0)+IF(Ayarlar!$B$27=Ayarlar!$E$22,N(AE7),0)+IF(Ayarlar!$B$28=Ayarlar!$E$22,N(AI7),0))/(IF(AND(Ayarlar!$B$21=Ayarlar!$E$22,ISNUMBER(G7)),IF(F7="",Ayarlar!$B$4,F7),0)+IF(AND(Ayarlar!$B$22=Ayarlar!$E$22,ISNUMBER(K7)),IF(J7="",Ayarlar!$B$5,J7),0)+IF(AND(Ayarlar!$B$23=Ayarlar!$E$22,ISNUMBER(O7)),IF(N7="",Ayarlar!$B$6,N7),0)+IF(AND(Ayarlar!$B$24=Ayarlar!$E$22,ISNUMBER(S7)),IF(R7="",Ayarlar!$B$7,R7),0)+IF(AND(Ayarlar!$B$25=Ayarlar!$E$22,ISNUMBER(W7)),IF(V7="",Ayarlar!$B$8,V7),0)+IF(AND(Ayarlar!$B$26=Ayarlar!$E$22,ISNUMBER(AA7)),IF(Z7="",Ayarlar!$B$9,Z7),0)+IF(AND(Ayarlar!$B$27=Ayarlar!$E$22,ISNUMBER(AE7)),IF(AD7="",Ayarlar!$B$10,AD7),0)+IF(AND(Ayarlar!$B$28=Ayarlar!$E$22,ISNUMBER(AI7)),IF(AH7="",Ayarlar!$B$11,AH7),0))*Ayarlar!$F$22,"") | AS7: =IFERROR((IF(Ayarlar!$B$21=Ayarlar!$E$23,N(G7),0)+IF(Ayarlar!$B$22=Ayarlar!$E$23,N(K7),0)+IF(Ayarlar!$B$23=Ayarlar!$E$23,N(O7),0)+IF(Ayarlar!$B$24=Ayarlar!$E$23,N(S7),0)+IF(Ayarlar!$B$25=Ayarlar!$E$23,N(W7),0)+IF(Ayarlar!$B$26=Ayarlar!$E$23,N(AA7),0)+IF(Ayarlar!$B$27=Ayarlar!$E$23,N(AE7),0)+IF(Ayarlar!$B$28=Ayarlar!$E$23,N(AI7),0))/(IF(AND(Ayarlar!$B$21=Ayarlar!$E$23,ISNUMBER(G7)),IF(F7="",Ayarlar!$B$4,F7),0)+IF(AND(Ayarlar!$B$22=Ayarlar!$E$23,ISNUMBER(K7)),IF(J7="",Ayarlar!$B$5,J7),0)+IF(AND(Ayarlar!$B$23=Ayarlar!$E$23,ISNUMBER(O7)),IF(N7="",Ayarlar!$B$6,N7),0)+IF(AND(Ayarlar!$B$24=Ayarlar!$E$23,ISNUMBER(S7)),IF(R7="",Ayarlar!$B$7,R7),0)+IF(AND(Ayarlar!$B$25=Ayarlar!$E$23,ISNUMBER(W7)),IF(V7="",Ayarlar!$B$8,V7),0)+IF(AND(Ayarlar!$B$26=Ayarlar!$E$23,ISNUMBER(AA7)),IF(Z7="",Ayarlar!$B$9,Z7),0)+IF(AND(Ayarlar!$B$27=Ayarlar!$E$23,ISNUMBER(AE7)),IF(AD7="",Ayarlar!$B$10,AD7),0)+IF(AND(Ayarlar!$B$28=Ayarlar!$E$23,ISNUMBER(AI7)),IF(AH7="",Ayarlar!$B$11,AH7),0))*Ayarlar!$F$23,"") | AT7: =IFERROR((IF(Ayarlar!$B$21=Ayarlar!$E$24,N(G7),0)+IF(Ayarlar!$B$22=Ayarlar!$E$24,N(K7),0)+IF(Ayarlar!$B$23=Ayarlar!$E$24,N(O7),0)+IF(Ayarlar!$B$24=Ayarlar!$E$24,N(S7),0)+IF(Ayarlar!$B$25=Ayarlar!$E$24,N(W7),0)+IF(Ayarlar!$B$26=Ayarlar!$E$24,N(AA7),0)+IF(Ayarlar!$B$27=Ayarlar!$E$24,N(AE7),0)+IF(Ayarlar!$B$28=Ayarlar!$E$24,N(AI7),0))/(IF(AND(Ayarlar!$B$21=Ayarlar!$E$24,ISNUMBER(G7)),IF(F7="",Ayarlar!$B$4,F7),0)+IF(AND(Ayarlar!$B$22=Ayarlar!$E$24,ISNUMBER(K7)),IF(J7="",Ayarlar!$B$5,J7),0)+IF(AND(Ayarlar!$B$23=Ayarlar!$E$24,ISNUMBER(O7)),IF(N7="",Ayarlar!$B$6,N7),0)+IF(AND(Ayarlar!$B$24=Ayarlar!$E$24,ISNUMBER(S7)),IF(R7="",Ayarlar!$B$7,R7),0)+IF(AND(Ayarlar!$B$25=Ayarlar!$E$24,ISNUMBER(W7)),IF(V7="",Ayarlar!$B$8,V7),0)+IF(AND(Ayarlar!$B$26=Ayarlar!$E$24,ISNUMBER(AA7)),IF(Z7="",Ayarlar!$B$9,Z7),0)+IF(AND(Ayarlar!$B$27=Ayarlar!$E$24,ISNUMBER(AE7)),IF(AD7="",Ayarlar!$B$10,AD7),0)+IF(AND(Ayarlar!$B$28=Ayarlar!$E$24,ISNUMBER(AI7)),IF(AH7="",Ayarlar!$B$11,AH7),0))*Ayarlar!$F$24,"") | AU7: =IF(COUNT(AQ7,AR7,AS7,AT7)<4,"",Ayarlar!$F$25+AQ7*Ayarlar!$G$21+AR7*Ayarlar!$G$22+AS7*Ayarlar!$G$23+AT7*Ayarlar!$G$24)
A8: 4 | G8: =IF(AND(D8="",E8=""),"",D8-IF(Ayarlar!$B$16>0,E8/Ayarlar!$B$16,0)) | K8: =IF(AND(H8="",I8=""),"",H8-IF(Ayarlar!$B$16>0,I8/Ayarlar!$B$16,0)) | O8: =IF(AND(L8="",M8=""),"",L8-IF(Ayarlar!$B$16>0,M8/Ayarlar!$B$16,0)) | S8: =IF(AND(P8="",Q8=""),"",P8-IF(Ayarlar!$B$16>0,Q8/Ayarlar!$B$16,0)) | W8: =IF(AND(T8="",U8=""),"",T8-IF(Ayarlar!$B$16>0,U8/Ayarlar!$B$16,0)) | AA8: =IF(AND(X8="",Y8=""),"",X8-IF(Ayarlar!$B$16>0,Y8/Ayarlar!$B$16,0)) | AE8: =IF(AND(AB8="",AC8=""),"",AB8-IF(Ayarlar!$B$16>0,AC8/Ayarlar!$B$16,0)) | AI8: =IF(AND(AF8="",AG8=""),"",AF8-IF(Ayarlar!$B$16>0,AG8/Ayarlar!$B$16,0)) | AJ8: =IF(COUNT(D8,E8,H8,I8,L8,M8,P8,Q8,T8,U8,X8,Y8,AB8,AC8,AF8,AG8)=0,"",D8+H8+L8+P8+T8+X8+AB8+AF8) | AK8: =IF(COUNT(D8,E8,H8,I8,L8,M8,P8,Q8,T8,U8,X8,Y8,AB8,AC8,AF8,AG8)=0,"",E8+I8+M8+Q8+U8+Y8+AC8+AG8) | AL8: =IF(COUNT(D8,E8,H8,I8,L8,M8,P8,Q8,T8,U8,X8,Y8,AB8,AC8,AF8,AG8)=0,"",IF(ISNUMBER(G8),IF(F8="",Ayarlar!$B$4,F8),0)+IF(ISNUMBER(K8),IF(J8="",Ayarlar!$B$5,J8),0)+IF(ISNUMBER(O8),IF(N8="",Ayarlar!$B$6,N8),0)+IF(ISNUMBER(S8),IF(R8="",Ayarlar!$B$7,R8),0)+IF(ISNUMBER(W8),IF(V8="",Ayarlar!$B$8,V8),0)+IF(ISNUMBER(AA8),IF(Z8="",Ayarlar!$B$9,Z8),0)+IF(ISNUMBER(AE8),IF(AD8="",Ayarlar!$B$10,AD8),0)+IF(ISNUMBER(AI8),IF(AH8="",Ayarlar!$B$11,AH8),0)) | AM8: =IF(COUNT(D8,E8,H8,I8,L8,M8,P8,Q8,T8,U8,X8,Y8,AB8,AC8,AF8,AG8)=0,"",AL8-AJ8-AK8) | AN8: =IF(COUNT(D8,E8,H8,I8,L8,M8,P8,Q8,T8,U8,X8,Y8,AB8,AC8,AF8,AG8)=0,"",SUM(G8,K8,O8,S8,W8,AA8,AE8,AI8)) | AO8: =IF(OR(COUNT(D8,E8,H8,I8,L8,M8,P8,Q8,T8,U8,X8,Y8,AB8,AC8,AF8,AG8)=0,N(AL8)=0),"",AN8/AL8) | AP8: =IF(OR(AO8="",AO7=""),"",AO8-AO7) | AQ8: =IFERROR((IF(Ayarlar!$B$21=Ayarlar!$E$21,N(G8),0)+IF(Ayarlar!$B$22=Ayarlar!$E$21,N(K8),0)+IF(Ayarlar!$B$23=Ayarlar!$E$21,N(O8),0)+IF(Ayarlar!$B$24=Ayarlar!$E$21,N(S8),0)+IF(Ayarlar!$B$25=Ayarlar!$E$21,N(W8),0)+IF(Ayarlar!$B$26=Ayarlar!$E$21,N(AA8),0)+IF(Ayarlar!$B$27=Ayarlar!$E$21,N(AE8),0)+IF(Ayarlar!$B$28=Ayarlar!$E$21,N(AI8),0))/(IF(AND(Ayarlar!$B$21=Ayarlar!$E$21,ISNUMBER(G8)),IF(F8="",Ayarlar!$B$4,F8),0)+IF(AND(Ayarlar!$B$22=Ayarlar!$E$21,ISNUMBER(K8)),IF(J8="",Ayarlar!$B$5,J8),0)+IF(AND(Ayarlar!$B$23=Ayarlar!$E$21,ISNUMBER(O8)),IF(N8="",Ayarlar!$B$6,N8),0)+IF(AND(Ayarlar!$B$24=Ayarlar!$E$21,ISNUMBER(S8)),IF(R8="",Ayarlar!$B$7,R8),0)+IF(AND(Ayarlar!$B$25=Ayarlar!$E$21,ISNUMBER(W8)),IF(V8="",Ayarlar!$B$8,V8),0)+IF(AND(Ayarlar!$B$26=Ayarlar!$E$21,ISNUMBER(AA8)),IF(Z8="",Ayarlar!$B$9,Z8),0)+IF(AND(Ayarlar!$B$27=Ayarlar!$E$21,ISNUMBER(AE8)),IF(AD8="",Ayarlar!$B$10,AD8),0)+IF(AND(Ayarlar!$B$28=Ayarlar!$E$21,ISNUMBER(AI8)),IF(AH8="",Ayarlar!$B$11,AH8),0))*Ayarlar!$F$21,"") | AR8: =IFERROR((IF(Ayarlar!$B$21=Ayarlar!$E$22,N(G8),0)+IF(Ayarlar!$B$22=Ayarlar!$E$22,N(K8),0)+IF(Ayarlar!$B$23=Ayarlar!$E$22,N(O8),0)+IF(Ayarlar!$B$24=Ayarlar!$E$22,N(S8),0)+IF(Ayarlar!$B$25=Ayarlar!$E$22,N(W8),0)+IF(Ayarlar!$B$26=Ayarlar!$E$22,N(AA8),0)+IF(Ayarlar!$B$27=Ayarlar!$E$22,N(AE8),0)+IF(Ayarlar!$B$28=Ayarlar!$E$22,N(AI8),0))/(IF(AND(Ayarlar!$B$21=Ayarlar!$E$22,ISNUMBER(G8)),IF(F8="",Ayarlar!$B$4,F8),0)+IF(AND(Ayarlar!$B$22=Ayarlar!$E$22,ISNUMBER(K8)),IF(J8="",Ayarlar!$B$5,J8),0)+IF(AND(Ayarlar!$B$23=Ayarlar!$E$22,ISNUMBER(O8)),IF(N8="",Ayarlar!$B$6,N8),0)+IF(AND(Ayarlar!$B$24=Ayarlar!$E$22,ISNUMBER(S8)),IF(R8="",Ayarlar!$B$7,R8),0)+IF(AND(Ayarlar!$B$25=Ayarlar!$E$22,ISNUMBER(W8)),IF(V8="",Ayarlar!$B$8,V8),0)+IF(AND(Ayarlar!$B$26=Ayarlar!$E$22,ISNUMBER(AA8)),IF(Z8="",Ayarlar!$B$9,Z8),0)+IF(AND(Ayarlar!$B$27=Ayarlar!$E$22,ISNUMBER(AE8)),IF(AD8="",Ayarlar!$B$10,AD8),0)+IF(AND(Ayarlar!$B$28=Ayarlar!$E$22,ISNUMBER(AI8)),IF(AH8="",Ayarlar!$B$11,AH8),0))*Ayarlar!$F$22,"") | AS8: =IFERROR((IF(Ayarlar!$B$21=Ayarlar!$E$23,N(G8),0)+IF(Ayarlar!$B$22=Ayarlar!$E$23,N(K8),0)+IF(Ayarlar!$B$23=Ayarlar!$E$23,N(O8),0)+IF(Ayarlar!$B$24=Ayarlar!$E$23,N(S8),0)+IF(Ayarlar!$B$25=Ayarlar!$E$23,N(W8),0)+IF(Ayarlar!$B$26=Ayarlar!$E$23,N(AA8),0)+IF(Ayarlar!$B$27=Ayarlar!$E$23,N(AE8),0)+IF(Ayarlar!$B$28=Ayarlar!$E$23,N(AI8),0))/(IF(AND(Ayarlar!$B$21=Ayarlar!$E$23,ISNUMBER(G8)),IF(F8="",Ayarlar!$B$4,F8),0)+IF(AND(Ayarlar!$B$22=Ayarlar!$E$23,ISNUMBER(K8)),IF(J8="",Ayarlar!$B$5,J8),0)+IF(AND(Ayarlar!$B$23=Ayarlar!$E$23,ISNUMBER(O8)),IF(N8="",Ayarlar!$B$6,N8),0)+IF(AND(Ayarlar!$B$24=Ayarlar!$E$23,ISNUMBER(S8)),IF(R8="",Ayarlar!$B$7,R8),0)+IF(AND(Ayarlar!$B$25=Ayarlar!$E$23,ISNUMBER(W8)),IF(V8="",Ayarlar!$B$8,V8),0)+IF(AND(Ayarlar!$B$26=Ayarlar!$E$23,ISNUMBER(AA8)),IF(Z8="",Ayarlar!$B$9,Z8),0)+IF(AND(Ayarlar!$B$27=Ayarlar!$E$23,ISNUMBER(AE8)),IF(AD8="",Ayarlar!$B$10,AD8),0)+IF(AND(Ayarlar!$B$28=Ayarlar!$E$23,ISNUMBER(AI8)),IF(AH8="",Ayarlar!$B$11,AH8),0))*Ayarlar!$F$23,"") | AT8: =IFERROR((IF(Ayarlar!$B$21=Ayarlar!$E$24,N(G8),0)+IF(Ayarlar!$B$22=Ayarlar!$E$24,N(K8),0)+IF(Ayarlar!$B$23=Ayarlar!$E$24,N(O8),0)+IF(Ayarlar!$B$24=Ayarlar!$E$24,N(S8),0)+IF(Ayarlar!$B$25=Ayarlar!$E$24,N(W8),0)+IF(Ayarlar!$B$26=Ayarlar!$E$24,N(AA8),0)+IF(Ayarlar!$B$27=Ayarlar!$E$24,N(AE8),0)+IF(Ayarlar!$B$28=Ayarlar!$E$24,N(AI8),0))/(IF(AND(Ayarlar!$B$21=Ayarlar!$E$24,ISNUMBER(G8)),IF(F8="",Ayarlar!$B$4,F8),0)+IF(AND(Ayarlar!$B$22=Ayarlar!$E$24,ISNUMBER(K8)),IF(J8="",Ayarlar!$B$5,J8),0)+IF(AND(Ayarlar!$B$23=Ayarlar!$E$24,ISNUMBER(O8)),IF(N8="",Ayarlar!$B$6,N8),0)+IF(AND(Ayarlar!$B$24=Ayarlar!$E$24,ISNUMBER(S8)),IF(R8="",Ayarlar!$B$7,R8),0)+IF(AND(Ayarlar!$B$25=Ayarlar!$E$24,ISNUMBER(W8)),IF(V8="",Ayarlar!$B$8,V8),0)+IF(AND(Ayarlar!$B$26=Ayarlar!$E$24,ISNUMBER(AA8)),IF(Z8="",Ayarlar!$B$9,Z8),0)+IF(AND(Ayarlar!$B$27=Ayarlar!$E$24,ISNUMBER(AE8)),IF(AD8="",Ayarlar!$B$10,AD8),0)+IF(AND(Ayarlar!$B$28=Ayarlar!$E$24,ISNUMBER(AI8)),IF(AH8="",Ayarlar!$B$11,AH8),0))*Ayarlar!$F$24,"") | AU8: =IF(COUNT(AQ8,AR8,AS8,AT8)<4,"",Ayarlar!$F$25+AQ8*Ayarlar!$G$21+AR8*Ayarlar!$G$22+AS8*Ayarlar!$G$23+AT8*Ayarlar!$G$24)
A9: 5 | G9: =IF(AND(D9="",E9=""),"",D9-IF(Ayarlar!$B$16>0,E9/Ayarlar!$B$16,0)) | K9: =IF(AND(H9="",I9=""),"",H9-IF(Ayarlar!$B$16>0,I9/Ayarlar!$B$16,0)) | O9: =IF(AND(L9="",M9=""),"",L9-IF(Ayarlar!$B$16>0,M9/Ayarlar!$B$16,0)) | S9: =IF(AND(P9="",Q9=""),"",P9-IF(Ayarlar!$B$16>0,Q9/Ayarlar!$B$16,0)) | W9: =IF(AND(T9="",U9=""),"",T9-IF(Ayarlar!$B$16>0,U9/Ayarlar!$B$16,0)) | AA9: =IF(AND(X9="",Y9=""),"",X9-IF(Ayarlar!$B$16>0,Y9/Ayarlar!$B$16,0)) | AE9: =IF(AND(AB9="",AC9=""),"",AB9-IF(Ayarlar!$B$16>0,AC9/Ayarlar!$B$16,0)) | AI9: =IF(AND(AF9="",AG9=""),"",AF9-IF(Ayarlar!$B$16>0,AG9/Ayarlar!$B$16,0)) | AJ9: =IF(COUNT(D9,E9,H9,I9,L9,M9,P9,Q9,T9,U9,X9,Y9,AB9,AC9,AF9,AG9)=0,"",D9+H9+L9+P9+T9+X9+AB9+AF9) | AK9: =IF(COUNT(D9,E9,H9,I9,L9,M9,P9,Q9,T9,U9,X9,Y9,AB9,AC9,AF9,AG9)=0,"",E9+I9+M9+Q9+U9+Y9+AC9+AG9) | AL9: =IF(COUNT(D9,E9,H9,I9,L9,M9,P9,Q9,T9,U9,X9,Y9,AB9,AC9,AF9,AG9)=0,"",IF(ISNUMBER(G9),IF(F9="",Ayarlar!$B$4,F9),0)+IF(ISNUMBER(K9),IF(J9="",Ayarlar!$B$5,J9),0)+IF(ISNUMBER(O9),IF(N9="",Ayarlar!$B$6,N9),0)+IF(ISNUMBER(S9),IF(R9="",Ayarlar!$B$7,R9),0)+IF(ISNUMBER(W9),IF(V9="",Ayarlar!$B$8,V9),0)+IF(ISNUMBER(AA9),IF(Z9="",Ayarlar!$B$9,Z9),0)+IF(ISNUMBER(AE9),IF(AD9="",Ayarlar!$B$10,AD9),0)+IF(ISNUMBER(AI9),IF(AH9="",Ayarlar!$B$11,AH9),0)) | AM9: =IF(COUNT(D9,E9,H9,I9,L9,M9,P9,Q9,T9,U9,X9,Y9,AB9,AC9,AF9,AG9)=0,"",AL9-AJ9-AK9) | AN9: =IF(COUNT(D9,E9,H9,I9,L9,M9,P9,Q9,T9,U9,X9,Y9,AB9,AC9,AF9,AG9)=0,"",SUM(G9,K9,O9,S9,W9,AA9,AE9,AI9)) | AO9: =IF(OR(COUNT(D9,E9,H9,I9,L9,M9,P9,Q9,T9,U9,X9,Y9,AB9,AC9,AF9,AG9)=0,N(AL9)=0),"",AN9/AL9) | AP9: =IF(OR(AO9="",AO8=""),"",AO9-AO8) | AQ9: =IFERROR((IF(Ayarlar!$B$21=Ayarlar!$E$21,N(G9),0)+IF(Ayarlar!$B$22=Ayarlar!$E$21,N(K9),0)+IF(Ayarlar!$B$23=Ayarlar!$E$21,N(O9),0)+IF(Ayarlar!$B$24=Ayarlar!$E$21,N(S9),0)+IF(Ayarlar!$B$25=Ayarlar!$E$21,N(W9),0)+IF(Ayarlar!$B$26=Ayarlar!$E$21,N(AA9),0)+IF(Ayarlar!$B$27=Ayarlar!$E$21,N(AE9),0)+IF(Ayarlar!$B$28=Ayarlar!$E$21,N(AI9),0))/(IF(AND(Ayarlar!$B$21=Ayarlar!$E$21,ISNUMBER(G9)),IF(F9="",Ayarlar!$B$4,F9),0)+IF(AND(Ayarlar!$B$22=Ayarlar!$E$21,ISNUMBER(K9)),IF(J9="",Ayarlar!$B$5,J9),0)+IF(AND(Ayarlar!$B$23=Ayarlar!$E$21,ISNUMBER(O9)),IF(N9="",Ayarlar!$B$6,N9),0)+IF(AND(Ayarlar!$B$24=Ayarlar!$E$21,ISNUMBER(S9)),IF(R9="",Ayarlar!$B$7,R9),0)+IF(AND(Ayarlar!$B$25=Ayarlar!$E$21,ISNUMBER(W9)),IF(V9="",Ayarlar!$B$8,V9),0)+IF(AND(Ayarlar!$B$26=Ayarlar!$E$21,ISNUMBER(AA9)),IF(Z9="",Ayarlar!$B$9,Z9),0)+IF(AND(Ayarlar!$B$27=Ayarlar!$E$21,ISNUMBER(AE9)),IF(AD9="",Ayarlar!$B$10,AD9),0)+IF(AND(Ayarlar!$B$28=Ayarlar!$E$21,ISNUMBER(AI9)),IF(AH9="",Ayarlar!$B$11,AH9),0))*Ayarlar!$F$21,"") | AR9: =IFERROR((IF(Ayarlar!$B$21=Ayarlar!$E$22,N(G9),0)+IF(Ayarlar!$B$22=Ayarlar!$E$22,N(K9),0)+IF(Ayarlar!$B$23=Ayarlar!$E$22,N(O9),0)+IF(Ayarlar!$B$24=Ayarlar!$E$22,N(S9),0)+IF(Ayarlar!$B$25=Ayarlar!$E$22,N(W9),0)+IF(Ayarlar!$B$26=Ayarlar!$E$22,N(AA9),0)+IF(Ayarlar!$B$27=Ayarlar!$E$22,N(AE9),0)+IF(Ayarlar!$B$28=Ayarlar!$E$22,N(AI9),0))/(IF(AND(Ayarlar!$B$21=Ayarlar!$E$22,ISNUMBER(G9)),IF(F9="",Ayarlar!$B$4,F9),0)+IF(AND(Ayarlar!$B$22=Ayarlar!$E$22,ISNUMBER(K9)),IF(J9="",Ayarlar!$B$5,J9),0)+IF(AND(Ayarlar!$B$23=Ayarlar!$E$22,ISNUMBER(O9)),IF(N9="",Ayarlar!$B$6,N9),0)+IF(AND(Ayarlar!$B$24=Ayarlar!$E$22,ISNUMBER(S9)),IF(R9="",Ayarlar!$B$7,R9),0)+IF(AND(Ayarlar!$B$25=Ayarlar!$E$22,ISNUMBER(W9)),IF(V9="",Ayarlar!$B$8,V9),0)+IF(AND(Ayarlar!$B$26=Ayarlar!$E$22,ISNUMBER(AA9)),IF(Z9="",Ayarlar!$B$9,Z9),0)+IF(AND(Ayarlar!$B$27=Ayarlar!$E$22,ISNUMBER(AE9)),IF(AD9="",Ayarlar!$B$10,AD9),0)+IF(AND(Ayarlar!$B$28=Ayarlar!$E$22,ISNUMBER(AI9)),IF(AH9="",Ayarlar!$B$11,AH9),0))*Ayarlar!$F$22,"") | AS9: =IFERROR((IF(Ayarlar!$B$21=Ayarlar!$E$23,N(G9),0)+IF(Ayarlar!$B$22=Ayarlar!$E$23,N(K9),0)+IF(Ayarlar!$B$23=Ayarlar!$E$23,N(O9),0)+IF(Ayarlar!$B$24=Ayarlar!$E$23,N(S9),0)+IF(Ayarlar!$B$25=Ayarlar!$E$23,N(W9),0)+IF(Ayarlar!$B$26=Ayarlar!$E$23,N(AA9),0)+IF(Ayarlar!$B$27=Ayarlar!$E$23,N(AE9),0)+IF(Ayarlar!$B$28=Ayarlar!$E$23,N(AI9),0))/(IF(AND(Ayarlar!$B$21=Ayarlar!$E$23,ISNUMBER(G9)),IF(F9="",Ayarlar!$B$4,F9),0)+IF(AND(Ayarlar!$B$22=Ayarlar!$E$23,ISNUMBER(K9)),IF(J9="",Ayarlar!$B$5,J9),0)+IF(AND(Ayarlar!$B$23=Ayarlar!$E$23,ISNUMBER(O9)),IF(N9="",Ayarlar!$B$6,N9),0)+IF(AND(Ayarlar!$B$24=Ayarlar!$E$23,ISNUMBER(S9)),IF(R9="",Ayarlar!$B$7,R9),0)+IF(AND(Ayarlar!$B$25=Ayarlar!$E$23,ISNUMBER(W9)),IF(V9="",Ayarlar!$B$8,V9),0)+IF(AND(Ayarlar!$B$26=Ayarlar!$E$23,ISNUMBER(AA9)),IF(Z9="",Ayarlar!$B$9,Z9),0)+IF(AND(Ayarlar!$B$27=Ayarlar!$E$23,ISNUMBER(AE9)),IF(AD9="",Ayarlar!$B$10,AD9),0)+IF(AND(Ayarlar!$B$28=Ayarlar!$E$23,ISNUMBER(AI9)),IF(AH9="",Ayarlar!$B$11,AH9),0))*Ayarlar!$F$23,"") | AT9: =IFERROR((IF(Ayarlar!$B$21=Ayarlar!$E$24,N(G9),0)+IF(Ayarlar!$B$22=Ayarlar!$E$24,N(K9),0)+IF(Ayarlar!$B$23=Ayarlar!$E$24,N(O9),0)+IF(Ayarlar!$B$24=Ayarlar!$E$24,N(S9),0)+IF(Ayarlar!$B$25=Ayarlar!$E$24,N(W9),0)+IF(Ayarlar!$B$26=Ayarlar!$E$24,N(AA9),0)+IF(Ayarlar!$B$27=Ayarlar!$E$24,N(AE9),0)+IF(Ayarlar!$B$28=Ayarlar!$E$24,N(AI9),0))/(IF(AND(Ayarlar!$B$21=Ayarlar!$E$24,ISNUMBER(G9)),IF(F9="",Ayarlar!$B$4,F9),0)+IF(AND(Ayarlar!$B$22=Ayarlar!$E$24,ISNUMBER(K9)),IF(J9="",Ayarlar!$B$5,J9),0)+IF(AND(Ayarlar!$B$23=Ayarlar!$E$24,ISNUMBER(O9)),IF(N9="",Ayarlar!$B$6,N9),0)+IF(AND(Ayarlar!$B$24=Ayarlar!$E$24,ISNUMBER(S9)),IF(R9="",Ayarlar!$B$7,R9),0)+IF(AND(Ayarlar!$B$25=Ayarlar!$E$24,ISNUMBER(W9)),IF(V9="",Ayarlar!$B$8,V9),0)+IF(AND(Ayarlar!$B$26=Ayarlar!$E$24,ISNUMBER(AA9)),IF(Z9="",Ayarlar!$B$9,Z9),0)+IF(AND(Ayarlar!$B$27=Ayarlar!$E$24,ISNUMBER(AE9)),IF(AD9="",Ayarlar!$B$10,AD9),0)+IF(AND(Ayarlar!$B$28=Ayarlar!$E$24,ISNUMBER(AI9)),IF(AH9="",Ayarlar!$B$11,AH9),0))*Ayarlar!$F$24,"") | AU9: =IF(COUNT(AQ9,AR9,AS9,AT9)<4,"",Ayarlar!$F$25+AQ9*Ayarlar!$G$21+AR9*Ayarlar!$G$22+AS9*Ayarlar!$G$23+AT9*Ayarlar!$G$24)
A10: 6 | G10: =IF(AND(D10="",E10=""),"",D10-IF(Ayarlar!$B$16>0,E10/Ayarlar!$B$16,0)) | K10: =IF(AND(H10="",I10=""),"",H10-IF(Ayarlar!$B$16>0,I10/Ayarlar!$B$16,0)) | O10: =IF(AND(L10="",M10=""),"",L10-IF(Ayarlar!$B$16>0,M10/Ayarlar!$B$16,0)) | S10: =IF(AND(P10="",Q10=""),"",P10-IF(Ayarlar!$B$16>0,Q10/Ayarlar!$B$16,0)) | W10: =IF(AND(T10="",U10=""),"",T10-IF(Ayarlar!$B$16>0,U10/Ayarlar!$B$16,0)) | AA10: =IF(AND(X10="",Y10=""),"",X10-IF(Ayarlar!$B$16>0,Y10/Ayarlar!$B$16,0)) | AE10: =IF(AND(AB10="",AC10=""),"",AB10-IF(Ayarlar!$B$16>0,AC10/Ayarlar!$B$16,0)) | AI10: =IF(AND(AF10="",AG10=""),"",AF10-IF(Ayarlar!$B$16>0,AG10/Ayarlar!$B$16,0)) | AJ10: =IF(COUNT(D10,E10,H10,I10,L10,M10,P10,Q10,T10,U10,X10,Y10,AB10,AC10,AF10,AG10)=0,"",D10+H10+L10+P10+T10+X10+AB10+AF10) | AK10: =IF(COUNT(D10,E10,H10,I10,L10,M10,P10,Q10,T10,U10,X10,Y10,AB10,AC10,AF10,AG10)=0,"",E10+I10+M10+Q10+U10+Y10+AC10+AG10) | AL10: =IF(COUNT(D10,E10,H10,I10,L10,M10,P10,Q10,T10,U10,X10,Y10,AB10,AC10,AF10,AG10)=0,"",IF(ISNUMBER(G10),IF(F10="",Ayarlar!$B$4,F10),0)+IF(ISNUMBER(K10),IF(J10="",Ayarlar!$B$5,J10),0)+IF(ISNUMBER(O10),IF(N10="",Ayarlar!$B$6,N10),0)+IF(ISNUMBER(S10),IF(R10="",Ayarlar!$B$7,R10),0)+IF(ISNUMBER(W10),IF(V10="",Ayarlar!$B$8,V10),0)+IF(ISNUMBER(AA10),IF(Z10="",Ayarlar!$B$9,Z10),0)+IF(ISNUMBER(AE10),IF(AD10="",Ayarlar!$B$10,AD10),0)+IF(ISNUMBER(AI10),IF(AH10="",Ayarlar!$B$11,AH10),0)) | AM10: =IF(COUNT(D10,E10,H10,I10,L10,M10,P10,Q10,T10,U10,X10,Y10,AB10,AC10,AF10,AG10)=0,"",AL10-AJ10-AK10) | AN10: =IF(COUNT(D10,E10,H10,I10,L10,M10,P10,Q10,T10,U10,X10,Y10,AB10,AC10,AF10,AG10)=0,"",SUM(G10,K10,O10,S10,W10,AA10,AE10,AI10)) | AO10: =IF(OR(COUNT(D10,E10,H10,I10,L10,M10,P10,Q10,T10,U10,X10,Y10,AB10,AC10,AF10,AG10)=0,N(AL10)=0),"",AN10/AL10) | AP10: =IF(OR(AO10="",AO9=""),"",AO10-AO9) | AQ10: =IFERROR((IF(Ayarlar!$B$21=Ayarlar!$E$21,N(G10),0)+IF(Ayarlar!$B$22=Ayarlar!$E$21,N(K10),0)+IF(Ayarlar!$B$23=Ayarlar!$E$21,N(O10),0)+IF(Ayarlar!$B$24=Ayarlar!$E$21,N(S10),0)+IF(Ayarlar!$B$25=Ayarlar!$E$21,N(W10),0)+IF(Ayarlar!$B$26=Ayarlar!$E$21,N(AA10),0)+IF(Ayarlar!$B$27=Ayarlar!$E$21,N(AE10),0)+IF(Ayarlar!$B$28=Ayarlar!$E$21,N(AI10),0))/(IF(AND(Ayarlar!$B$21=Ayarlar!$E$21,ISNUMBER(G10)),IF(F10="",Ayarlar!$B$4,F10),0)+IF(AND(Ayarlar!$B$22=Ayarlar!$E$21,ISNUMBER(K10)),IF(J10="",Ayarlar!$B$5,J10),0)+IF(AND(Ayarlar!$B$23=Ayarlar!$E$21,ISNUMBER(O10)),IF(N10="",Ayarlar!$B$6,N10),0)+IF(AND(Ayarlar!$B$24=Ayarlar!$E$21,ISNUMBER(S10)),IF(R10="",Ayarlar!$B$7,R10),0)+IF(AND(Ayarlar!$B$25=Ayarlar!$E$21,ISNUMBER(W10)),IF(V10="",Ayarlar!$B$8,V10),0)+IF(AND(Ayarlar!$B$26=Ayarlar!$E$21,ISNUMBER(AA10)),IF(Z10="",Ayarlar!$B$9,Z10),0)+IF(AND(Ayarlar!$B$27=Ayarlar!$E$21,ISNUMBER(AE10)),IF(AD10="",Ayarlar!$B$10,AD10),0)+IF(AND(Ayarlar!$B$28=Ayarlar!$E$21,ISNUMBER(AI10)),IF(AH10="",Ayarlar!$B$11,AH10),0))*Ayarlar!$F$21,"") | AR10: =IFERROR((IF(Ayarlar!$B$21=Ayarlar!$E$22,N(G10),0)+IF(Ayarlar!$B$22=Ayarlar!$E$22,N(K10),0)+IF(Ayarlar!$B$23=Ayarlar!$E$22,N(O10),0)+IF(Ayarlar!$B$24=Ayarlar!$E$22,N(S10),0)+IF(Ayarlar!$B$25=Ayarlar!$E$22,N(W10),0)+IF(Ayarlar!$B$26=Ayarlar!$E$22,N(AA10),0)+IF(Ayarlar!$B$27=Ayarlar!$E$22,N(AE10),0)+IF(Ayarlar!$B$28=Ayarlar!$E$22,N(AI10),0))/(IF(AND(Ayarlar!$B$21=Ayarlar!$E$22,ISNUMBER(G10)),IF(F10="",Ayarlar!$B$4,F10),0)+IF(AND(Ayarlar!$B$22=Ayarlar!$E$22,ISNUMBER(K10)),IF(J10="",Ayarlar!$B$5,J10),0)+IF(AND(Ayarlar!$B$23=Ayarlar!$E$22,ISNUMBER(O10)),IF(N10="",Ayarlar!$B$6,N10),0)+IF(AND(Ayarlar!$B$24=Ayarlar!$E$22,ISNUMBER(S10)),IF(R10="",Ayarlar!$B$7,R10),0)+IF(AND(Ayarlar!$B$25=Ayarlar!$E$22,ISNUMBER(W10)),IF(V10="",Ayarlar!$B$8,V10),0)+IF(AND(Ayarlar!$B$26=Ayarlar!$E$22,ISNUMBER(AA10)),IF(Z10="",Ayarlar!$B$9,Z10),0)+IF(AND(Ayarlar!$B$27=Ayarlar!$E$22,ISNUMBER(AE10)),IF(AD10="",Ayarlar!$B$10,AD10),0)+IF(AND(Ayarlar!$B$28=Ayarlar!$E$22,ISNUMBER(AI10)),IF(AH10="",Ayarlar!$B$11,AH10),0))*Ayarlar!$F$22,"") | AS10: =IFERROR((IF(Ayarlar!$B$21=Ayarlar!$E$23,N(G10),0)+IF(Ayarlar!$B$22=Ayarlar!$E$23,N(K10),0)+IF(Ayarlar!$B$23=Ayarlar!$E$23,N(O10),0)+IF(Ayarlar!$B$24=Ayarlar!$E$23,N(S10),0)+IF(Ayarlar!$B$25=Ayarlar!$E$23,N(W10),0)+IF(Ayarlar!$B$26=Ayarlar!$E$23,N(AA10),0)+IF(Ayarlar!$B$27=Ayarlar!$E$23,N(AE10),0)+IF(Ayarlar!$B$28=Ayarlar!$E$23,N(AI10),0))/(IF(AND(Ayarlar!$B$21=Ayarlar!$E$23,ISNUMBER(G10)),IF(F10="",Ayarlar!$B$4,F10),0)+IF(AND(Ayarlar!$B$22=Ayarlar!$E$23,ISNUMBER(K10)),IF(J10="",Ayarlar!$B$5,J10),0)+IF(AND(Ayarlar!$B$23=Ayarlar!$E$23,ISNUMBER(O10)),IF(N10="",Ayarlar!$B$6,N10),0)+IF(AND(Ayarlar!$B$24=Ayarlar!$E$23,ISNUMBER(S10)),IF(R10="",Ayarlar!$B$7,R10),0)+IF(AND(Ayarlar!$B$25=Ayarlar!$E$23,ISNUMBER(W10)),IF(V10="",Ayarlar!$B$8,V10),0)+IF(AND(Ayarlar!$B$26=Ayarlar!$E$23,ISNUMBER(AA10)),IF(Z10="",Ayarlar!$B$9,Z10),0)+IF(AND(Ayarlar!$B$27=Ayarlar!$E$23,ISNUMBER(AE10)),IF(AD10="",Ayarlar!$B$10,AD10),0)+IF(AND(Ayarlar!$B$28=Ayarlar!$E$23,ISNUMBER(AI10)),IF(AH10="",Ayarlar!$B$11,AH10),0))*Ayarlar!$F$23,"") | AT10: =IFERROR((IF(Ayarlar!$B$21=Ayarlar!$E$24,N(G10),0)+IF(Ayarlar!$B$22=Ayarlar!$E$24,N(K10),0)+IF(Ayarlar!$B$23=Ayarlar!$E$24,N(O10),0)+IF(Ayarlar!$B$24=Ayarlar!$E$24,N(S10),0)+IF(Ayarlar!$B$25=Ayarlar!$E$24,N(W10),0)+IF(Ayarlar!$B$26=Ayarlar!$E$24,N(AA10),0)+IF(Ayarlar!$B$27=Ayarlar!$E$24,N(AE10),0)+IF(Ayarlar!$B$28=Ayarlar!$E$24,N(AI10),0))/(IF(AND(Ayarlar!$B$21=Ayarlar!$E$24,ISNUMBER(G10)),IF(F10="",Ayarlar!$B$4,F10),0)+IF(AND(Ayarlar!$B$22=Ayarlar!$E$24,ISNUMBER(K10)),IF(J10="",Ayarlar!$B$5,J10),0)+IF(AND(Ayarlar!$B$23=Ayarlar!$E$24,ISNUMBER(O10)),IF(N10="",Ayarlar!$B$6,N10),0)+IF(AND(Ayarlar!$B$24=Ayarlar!$E$24,ISNUMBER(S10)),IF(R10="",Ayarlar!$B$7,R10),0)+IF(AND(Ayarlar!$B$25=Ayarlar!$E$24,ISNUMBER(W10)),IF(V10="",Ayarlar!$B$8,V10),0)+IF(AND(Ayarlar!$B$26=Ayarlar!$E$24,ISNUMBER(AA10)),IF(Z10="",Ayarlar!$B$9,Z10),0)+IF(AND(Ayarlar!$B$27=Ayarlar!$E$24,ISNUMBER(AE10)),IF(AD10="",Ayarlar!$B$10,AD10),0)+IF(AND(Ayarlar!$B$28=Ayarlar!$E$24,ISNUMBER(AI10)),IF(AH10="",Ayarlar!$B$11,AH10),0))*Ayarlar!$F$24,"") | AU10: =IF(COUNT(AQ10,AR10,AS10,AT10)<4,"",Ayarlar!$F$25+AQ10*Ayarlar!$G$21+AR10*Ayarlar!$G$22+AS10*Ayarlar!$G$23+AT10*Ayarlar!$G$24)
A11: 7 | G11: =IF(AND(D11="",E11=""),"",D11-IF(Ayarlar!$B$16>0,E11/Ayarlar!$B$16,0)) | K11: =IF(AND(H11="",I11=""),"",H11-IF(Ayarlar!$B$16>0,I11/Ayarlar!$B$16,0)) | O11: =IF(AND(L11="",M11=""),"",L11-IF(Ayarlar!$B$16>0,M11/Ayarlar!$B$16,0)) | S11: =IF(AND(P11="",Q11=""),"",P11-IF(Ayarlar!$B$16>0,Q11/Ayarlar!$B$16,0)) | W11: =IF(AND(T11="",U11=""),"",T11-IF(Ayarlar!$B$16>0,U11/Ayarlar!$B$16,0)) | AA11: =IF(AND(X11="",Y11=""),"",X11-IF(Ayarlar!$B$16>0,Y11/Ayarlar!$B$16,0)) | AE11: =IF(AND(AB11="",AC11=""),"",AB11-IF(Ayarlar!$B$16>0,AC11/Ayarlar!$B$16,0)) | AI11: =IF(AND(AF11="",AG11=""),"",AF11-IF(Ayarlar!$B$16>0,AG11/Ayarlar!$B$16,0)) | AJ11: =IF(COUNT(D11,E11,H11,I11,L11,M11,P11,Q11,T11,U11,X11,Y11,AB11,AC11,AF11,AG11)=0,"",D11+H11+L11+P11+T11+X11+AB11+AF11) | AK11: =IF(COUNT(D11,E11,H11,I11,L11,M11,P11,Q11,T11,U11,X11,Y11,AB11,AC11,AF11,AG11)=0,"",E11+I11+M11+Q11+U11+Y11+AC11+AG11) | AL11: =IF(COUNT(D11,E11,H11,I11,L11,M11,P11,Q11,T11,U11,X11,Y11,AB11,AC11,AF11,AG11)=0,"",IF(ISNUMBER(G11),IF(F11="",Ayarlar!$B$4,F11),0)+IF(ISNUMBER(K11),IF(J11="",Ayarlar!$B$5,J11),0)+IF(ISNUMBER(O11),IF(N11="",Ayarlar!$B$6,N11),0)+IF(ISNUMBER(S11),IF(R11="",Ayarlar!$B$7,R11),0)+IF(ISNUMBER(W11),IF(V11="",Ayarlar!$B$8,V11),0)+IF(ISNUMBER(AA11),IF(Z11="",Ayarlar!$B$9,Z11),0)+IF(ISNUMBER(AE11),IF(AD11="",Ayarlar!$B$10,AD11),0)+IF(ISNUMBER(AI11),IF(AH11="",Ayarlar!$B$11,AH11),0)) | AM11: =IF(COUNT(D11,E11,H11,I11,L11,M11,P11,Q11,T11,U11,X11,Y11,AB11,AC11,AF11,AG11)=0,"",AL11-AJ11-AK11) | AN11: =IF(COUNT(D11,E11,H11,I11,L11,M11,P11,Q11,T11,U11,X11,Y11,AB11,AC11,AF11,AG11)=0,"",SUM(G11,K11,O11,S11,W11,AA11,AE11,AI11)) | AO11: =IF(OR(COUNT(D11,E11,H11,I11,L11,M11,P11,Q11,T11,U11,X11,Y11,AB11,AC11,AF11,AG11)=0,N(AL11)=0),"",AN11/AL11) | AP11: =IF(OR(AO11="",AO10=""),"",AO11-AO10) | AQ11: =IFERROR((IF(Ayarlar!$B$21=Ayarlar!$E$21,N(G11),0)+IF(Ayarlar!$B$22=Ayarlar!$E$21,N(K11),0)+IF(Ayarlar!$B$23=Ayarlar!$E$21,N(O11),0)+IF(Ayarlar!$B$24=Ayarlar!$E$21,N(S11),0)+IF(Ayarlar!$B$25=Ayarlar!$E$21,N(W11),0)+IF(Ayarlar!$B$26=Ayarlar!$E$21,N(AA11),0)+IF(Ayarlar!$B$27=Ayarlar!$E$21,N(AE11),0)+IF(Ayarlar!$B$28=Ayarlar!$E$21,N(AI11),0))/(IF(AND(Ayarlar!$B$21=Ayarlar!$E$21,ISNUMBER(G11)),IF(F11="",Ayarlar!$B$4,F11),0)+IF(AND(Ayarlar!$B$22=Ayarlar!$E$21,ISNUMBER(K11)),IF(J11="",Ayarlar!$B$5,J11),0)+IF(AND(Ayarlar!$B$23=Ayarlar!$E$21,ISNUMBER(O11)),IF(N11="",Ayarlar!$B$6,N11),0)+IF(AND(Ayarlar!$B$24=Ayarlar!$E$21,ISNUMBER(S11)),IF(R11="",Ayarlar!$B$7,R11),0)+IF(AND(Ayarlar!$B$25=Ayarlar!$E$21,ISNUMBER(W11)),IF(V11="",Ayarlar!$B$8,V11),0)+IF(AND(Ayarlar!$B$26=Ayarlar!$E$21,ISNUMBER(AA11)),IF(Z11="",Ayarlar!$B$9,Z11),0)+IF(AND(Ayarlar!$B$27=Ayarlar!$E$21,ISNUMBER(AE11)),IF(AD11="",Ayarlar!$B$10,AD11),0)+IF(AND(Ayarlar!$B$28=Ayarlar!$E$21,ISNUMBER(AI11)),IF(AH11="",Ayarlar!$B$11,AH11),0))*Ayarlar!$F$21,"") | AR11: =IFERROR((IF(Ayarlar!$B$21=Ayarlar!$E$22,N(G11),0)+IF(Ayarlar!$B$22=Ayarlar!$E$22,N(K11),0)+IF(Ayarlar!$B$23=Ayarlar!$E$22,N(O11),0)+IF(Ayarlar!$B$24=Ayarlar!$E$22,N(S11),0)+IF(Ayarlar!$B$25=Ayarlar!$E$22,N(W11),0)+IF(Ayarlar!$B$26=Ayarlar!$E$22,N(AA11),0)+IF(Ayarlar!$B$27=Ayarlar!$E$22,N(AE11),0)+IF(Ayarlar!$B$28=Ayarlar!$E$22,N(AI11),0))/(IF(AND(Ayarlar!$B$21=Ayarlar!$E$22,ISNUMBER(G11)),IF(F11="",Ayarlar!$B$4,F11),0)+IF(AND(Ayarlar!$B$22=Ayarlar!$E$22,ISNUMBER(K11)),IF(J11="",Ayarlar!$B$5,J11),0)+IF(AND(Ayarlar!$B$23=Ayarlar!$E$22,ISNUMBER(O11)),IF(N11="",Ayarlar!$B$6,N11),0)+IF(AND(Ayarlar!$B$24=Ayarlar!$E$22,ISNUMBER(S11)),IF(R11="",Ayarlar!$B$7,R11),0)+IF(AND(Ayarlar!$B$25=Ayarlar!$E$22,ISNUMBER(W11)),IF(V11="",Ayarlar!$B$8,V11),0)+IF(AND(Ayarlar!$B$26=Ayarlar!$E$22,ISNUMBER(AA11)),IF(Z11="",Ayarlar!$B$9,Z11),0)+IF(AND(Ayarlar!$B$27=Ayarlar!$E$22,ISNUMBER(AE11)),IF(AD11="",Ayarlar!$B$10,AD11),0)+IF(AND(Ayarlar!$B$28=Ayarlar!$E$22,ISNUMBER(AI11)),IF(AH11="",Ayarlar!$B$11,AH11),0))*Ayarlar!$F$22,"") | AS11: =IFERROR((IF(Ayarlar!$B$21=Ayarlar!$E$23,N(G11),0)+IF(Ayarlar!$B$22=Ayarlar!$E$23,N(K11),0)+IF(Ayarlar!$B$23=Ayarlar!$E$23,N(O11),0)+IF(Ayarlar!$B$24=Ayarlar!$E$23,N(S11),0)+IF(Ayarlar!$B$25=Ayarlar!$E$23,N(W11),0)+IF(Ayarlar!$B$26=Ayarlar!$E$23,N(AA11),0)+IF(Ayarlar!$B$27=Ayarlar!$E$23,N(AE11),0)+IF(Ayarlar!$B$28=Ayarlar!$E$23,N(AI11),0))/(IF(AND(Ayarlar!$B$21=Ayarlar!$E$23,ISNUMBER(G11)),IF(F11="",Ayarlar!$B$4,F11),0)+IF(AND(Ayarlar!$B$22=Ayarlar!$E$23,ISNUMBER(K11)),IF(J11="",Ayarlar!$B$5,J11),0)+IF(AND(Ayarlar!$B$23=Ayarlar!$E$23,ISNUMBER(O11)),IF(N11="",Ayarlar!$B$6,N11),0)+IF(AND(Ayarlar!$B$24=Ayarlar!$E$23,ISNUMBER(S11)),IF(R11="",Ayarlar!$B$7,R11),0)+IF(AND(Ayarlar!$B$25=Ayarlar!$E$23,ISNUMBER(W11)),IF(V11="",Ayarlar!$B$8,V11),0)+IF(AND(Ayarlar!$B$26=Ayarlar!$E$23,ISNUMBER(AA11)),IF(Z11="",Ayarlar!$B$9,Z11),0)+IF(AND(Ayarlar!$B$27=Ayarlar!$E$23,ISNUMBER(AE11)),IF(AD11="",Ayarlar!$B$10,AD11),0)+IF(AND(Ayarlar!$B$28=Ayarlar!$E$23,ISNUMBER(AI11)),IF(AH11="",Ayarlar!$B$11,AH11),0))*Ayarlar!$F$23,"") | AT11: =IFERROR((IF(Ayarlar!$B$21=Ayarlar!$E$24,N(G11),0)+IF(Ayarlar!$B$22=Ayarlar!$E$24,N(K11),0)+IF(Ayarlar!$B$23=Ayarlar!$E$24,N(O11),0)+IF(Ayarlar!$B$24=Ayarlar!$E$24,N(S11),0)+IF(Ayarlar!$B$25=Ayarlar!$E$24,N(W11),0)+IF(Ayarlar!$B$26=Ayarlar!$E$24,N(AA11),0)+IF(Ayarlar!$B$27=Ayarlar!$E$24,N(AE11),0)+IF(Ayarlar!$B$28=Ayarlar!$E$24,N(AI11),0))/(IF(AND(Ayarlar!$B$21=Ayarlar!$E$24,ISNUMBER(G11)),IF(F11="",Ayarlar!$B$4,F11),0)+IF(AND(Ayarlar!$B$22=Ayarlar!$E$24,ISNUMBER(K11)),IF(J11="",Ayarlar!$B$5,J11),0)+IF(AND(Ayarlar!$B$23=Ayarlar!$E$24,ISNUMBER(O11)),IF(N11="",Ayarlar!$B$6,N11),0)+IF(AND(Ayarlar!$B$24=Ayarlar!$E$24,ISNUMBER(S11)),IF(R11="",Ayarlar!$B$7,R11),0)+IF(AND(Ayarlar!$B$25=Ayarlar!$E$24,ISNUMBER(W11)),IF(V11="",Ayarlar!$B$8,V11),0)+IF(AND(Ayarlar!$B$26=Ayarlar!$E$24,ISNUMBER(AA11)),IF(Z11="",Ayarlar!$B$9,Z11),0)+IF(AND(Ayarlar!$B$27=Ayarlar!$E$24,ISNUMBER(AE11)),IF(AD11="",Ayarlar!$B$10,AD11),0)+IF(AND(Ayarlar!$B$28=Ayarlar!$E$24,ISNUMBER(AI11)),IF(AH11="",Ayarlar!$B$11,AH11),0))*Ayarlar!$F$24,"") | AU11: =IF(COUNT(AQ11,AR11,AS11,AT11)<4,"",Ayarlar!$F$25+AQ11*Ayarlar!$G$21+AR11*Ayarlar!$G$22+AS11*Ayarlar!$G$23+AT11*Ayarlar!$G$24)
A12: 8 | G12: =IF(AND(D12="",E12=""),"",D12-IF(Ayarlar!$B$16>0,E12/Ayarlar!$B$16,0)) | K12: =IF(AND(H12="",I12=""),"",H12-IF(Ayarlar!$B$16>0,I12/Ayarlar!$B$16,0)) | O12: =IF(AND(L12="",M12=""),"",L12-IF(Ayarlar!$B$16>0,M12/Ayarlar!$B$16,0)) | S12: =IF(AND(P12="",Q12=""),"",P12-IF(Ayarlar!$B$16>0,Q12/Ayarlar!$B$16,0)) | W12: =IF(AND(T12="",U12=""),"",T12-IF(Ayarlar!$B$16>0,U12/Ayarlar!$B$16,0)) | AA12: =IF(AND(X12="",Y12=""),"",X12-IF(Ayarlar!$B$16>0,Y12/Ayarlar!$B$16,0)) | AE12: =IF(AND(AB12="",AC12=""),"",AB12-IF(Ayarlar!$B$16>0,AC12/Ayarlar!$B$16,0)) | AI12: =IF(AND(AF12="",AG12=""),"",AF12-IF(Ayarlar!$B$16>0,AG12/Ayarlar!$B$16,0)) | AJ12: =IF(COUNT(D12,E12,H12,I12,L12,M12,P12,Q12,T12,U12,X12,Y12,AB12,AC12,AF12,AG12)=0,"",D12+H12+L12+P12+T12+X12+AB12+AF12) | AK12: =IF(COUNT(D12,E12,H12,I12,L12,M12,P12,Q12,T12,U12,X12,Y12,AB12,AC12,AF12,AG12)=0,"",E12+I12+M12+Q12+U12+Y12+AC12+AG12) | AL12: =IF(COUNT(D12,E12,H12,I12,L12,M12,P12,Q12,T12,U12,X12,Y12,AB12,AC12,AF12,AG12)=0,"",IF(ISNUMBER(G12),IF(F12="",Ayarlar!$B$4,F12),0)+IF(ISNUMBER(K12),IF(J12="",Ayarlar!$B$5,J12),0)+IF(ISNUMBER(O12),IF(N12="",Ayarlar!$B$6,N12),0)+IF(ISNUMBER(S12),IF(R12="",Ayarlar!$B$7,R12),0)+IF(ISNUMBER(W12),IF(V12="",Ayarlar!$B$8,V12),0)+IF(ISNUMBER(AA12),IF(Z12="",Ayarlar!$B$9,Z12),0)+IF(ISNUMBER(AE12),IF(AD12="",Ayarlar!$B$10,AD12),0)+IF(ISNUMBER(AI12),IF(AH12="",Ayarlar!$B$11,AH12),0)) | AM12: =IF(COUNT(D12,E12,H12,I12,L12,M12,P12,Q12,T12,U12,X12,Y12,AB12,AC12,AF12,AG12)=0,"",AL12-AJ12-AK12) | AN12: =IF(COUNT(D12,E12,H12,I12,L12,M12,P12,Q12,T12,U12,X12,Y12,AB12,AC12,AF12,AG12)=0,"",SUM(G12,K12,O12,S12,W12,AA12,AE12,AI12)) | AO12: =IF(OR(COUNT(D12,E12,H12,I12,L12,M12,P12,Q12,T12,U12,X12,Y12,AB12,AC12,AF12,AG12)=0,N(AL12)=0),"",AN12/AL12) | AP12: =IF(OR(AO12="",AO11=""),"",AO12-AO11) | AQ12: =IFERROR((IF(Ayarlar!$B$21=Ayarlar!$E$21,N(G12),0)+IF(Ayarlar!$B$22=Ayarlar!$E$21,N(K12),0)+IF(Ayarlar!$B$23=Ayarlar!$E$21,N(O12),0)+IF(Ayarlar!$B$24=Ayarlar!$E$21,N(S12),0)+IF(Ayarlar!$B$25=Ayarlar!$E$21,N(W12),0)+IF(Ayarlar!$B$26=Ayarlar!$E$21,N(AA12),0)+IF(Ayarlar!$B$27=Ayarlar!$E$21,N(AE12),0)+IF(Ayarlar!$B$28=Ayarlar!$E$21,N(AI12),0))/(IF(AND(Ayarlar!$B$21=Ayarlar!$E$21,ISNUMBER(G12)),IF(F12="",Ayarlar!$B$4,F12),0)+IF(AND(Ayarlar!$B$22=Ayarlar!$E$21,ISNUMBER(K12)),IF(J12="",Ayarlar!$B$5,J12),0)+IF(AND(Ayarlar!$B$23=Ayarlar!$E$21,ISNUMBER(O12)),IF(N12="",Ayarlar!$B$6,N12),0)+IF(AND(Ayarlar!$B$24=Ayarlar!$E$21,ISNUMBER(S12)),IF(R12="",Ayarlar!$B$7,R12),0)+IF(AND(Ayarlar!$B$25=Ayarlar!$E$21,ISNUMBER(W12)),IF(V12="",Ayarlar!$B$8,V12),0)+IF(AND(Ayarlar!$B$26=Ayarlar!$E$21,ISNUMBER(AA12)),IF(Z12="",Ayarlar!$B$9,Z12),0)+IF(AND(Ayarlar!$B$27=Ayarlar!$E$21,ISNUMBER(AE12)),IF(AD12="",Ayarlar!$B$10,AD12),0)+IF(AND(Ayarlar!$B$28=Ayarlar!$E$21,ISNUMBER(AI12)),IF(AH12="",Ayarlar!$B$11,AH12),0))*Ayarlar!$F$21,"") | AR12: =IFERROR((IF(Ayarlar!$B$21=Ayarlar!$E$22,N(G12),0)+IF(Ayarlar!$B$22=Ayarlar!$E$22,N(K12),0)+IF(Ayarlar!$B$23=Ayarlar!$E$22,N(O12),0)+IF(Ayarlar!$B$24=Ayarlar!$E$22,N(S12),0)+IF(Ayarlar!$B$25=Ayarlar!$E$22,N(W12),0)+IF(Ayarlar!$B$26=Ayarlar!$E$22,N(AA12),0)+IF(Ayarlar!$B$27=Ayarlar!$E$22,N(AE12),0)+IF(Ayarlar!$B$28=Ayarlar!$E$22,N(AI12),0))/(IF(AND(Ayarlar!$B$21=Ayarlar!$E$22,ISNUMBER(G12)),IF(F12="",Ayarlar!$B$4,F12),0)+IF(AND(Ayarlar!$B$22=Ayarlar!$E$22,ISNUMBER(K12)),IF(J12="",Ayarlar!$B$5,J12),0)+IF(AND(Ayarlar!$B$23=Ayarlar!$E$22,ISNUMBER(O12)),IF(N12="",Ayarlar!$B$6,N12),0)+IF(AND(Ayarlar!$B$24=Ayarlar!$E$22,ISNUMBER(S12)),IF(R12="",Ayarlar!$B$7,R12),0)+IF(AND(Ayarlar!$B$25=Ayarlar!$E$22,ISNUMBER(W12)),IF(V12="",Ayarlar!$B$8,V12),0)+IF(AND(Ayarlar!$B$26=Ayarlar!$E$22,ISNUMBER(AA12)),IF(Z12="",Ayarlar!$B$9,Z12),0)+IF(AND(Ayarlar!$B$27=Ayarlar!$E$22,ISNUMBER(AE12)),IF(AD12="",Ayarlar!$B$10,AD12),0)+IF(AND(Ayarlar!$B$28=Ayarlar!$E$22,ISNUMBER(AI12)),IF(AH12="",Ayarlar!$B$11,AH12),0))*Ayarlar!$F$22,"") | AS12: =IFERROR((IF(Ayarlar!$B$21=Ayarlar!$E$23,N(G12),0)+IF(Ayarlar!$B$22=Ayarlar!$E$23,N(K12),0)+IF(Ayarlar!$B$23=Ayarlar!$E$23,N(O12),0)+IF(Ayarlar!$B$24=Ayarlar!$E$23,N(S12),0)+IF(Ayarlar!$B$25=Ayarlar!$E$23,N(W12),0)+IF(Ayarlar!$B$26=Ayarlar!$E$23,N(AA12),0)+IF(Ayarlar!$B$27=Ayarlar!$E$23,N(AE12),0)+IF(Ayarlar!$B$28=Ayarlar!$E$23,N(AI12),0))/(IF(AND(Ayarlar!$B$21=Ayarlar!$E$23,ISNUMBER(G12)),IF(F12="",Ayarlar!$B$4,F12),0)+IF(AND(Ayarlar!$B$22=Ayarlar!$E$23,ISNUMBER(K12)),IF(J12="",Ayarlar!$B$5,J12),0)+IF(AND(Ayarlar!$B$23=Ayarlar!$E$23,ISNUMBER(O12)),IF(N12="",Ayarlar!$B$6,N12),0)+IF(AND(Ayarlar!$B$24=Ayarlar!$E$23,ISNUMBER(S12)),IF(R12="",Ayarlar!$B$7,R12),0)+IF(AND(Ayarlar!$B$25=Ayarlar!$E$23,ISNUMBER(W12)),IF(V12="",Ayarlar!$B$8,V12),0)+IF(AND(Ayarlar!$B$26=Ayarlar!$E$23,ISNUMBER(AA12)),IF(Z12="",Ayarlar!$B$9,Z12),0)+IF(AND(Ayarlar!$B$27=Ayarlar!$E$23,ISNUMBER(AE12)),IF(AD12="",Ayarlar!$B$10,AD12),0)+IF(AND(Ayarlar!$B$28=Ayarlar!$E$23,ISNUMBER(AI12)),IF(AH12="",Ayarlar!$B$11,AH12),0))*Ayarlar!$F$23,"") | AT12: =IFERROR((IF(Ayarlar!$B$21=Ayarlar!$E$24,N(G12),0)+IF(Ayarlar!$B$22=Ayarlar!$E$24,N(K12),0)+IF(Ayarlar!$B$23=Ayarlar!$E$24,N(O12),0)+IF(Ayarlar!$B$24=Ayarlar!$E$24,N(S12),0)+IF(Ayarlar!$B$25=Ayarlar!$E$24,N(W12),0)+IF(Ayarlar!$B$26=Ayarlar!$E$24,N(AA12),0)+IF(Ayarlar!$B$27=Ayarlar!$E$24,N(AE12),0)+IF(Ayarlar!$B$28=Ayarlar!$E$24,N(AI12),0))/(IF(AND(Ayarlar!$B$21=Ayarlar!$E$24,ISNUMBER(G12)),IF(F12="",Ayarlar!$B$4,F12),0)+IF(AND(Ayarlar!$B$22=Ayarlar!$E$24,ISNUMBER(K12)),IF(J12="",Ayarlar!$B$5,J12),0)+IF(AND(Ayarlar!$B$23=Ayarlar!$E$24,ISNUMBER(O12)),IF(N12="",Ayarlar!$B$6,N12),0)+IF(AND(Ayarlar!$B$24=Ayarlar!$E$24,ISNUMBER(S12)),IF(R12="",Ayarlar!$B$7,R12),0)+IF(AND(Ayarlar!$B$25=Ayarlar!$E$24,ISNUMBER(W12)),IF(V12="",Ayarlar!$B$8,V12),0)+IF(AND(Ayarlar!$B$26=Ayarlar!$E$24,ISNUMBER(AA12)),IF(Z12="",Ayarlar!$B$9,Z12),0)+IF(AND(Ayarlar!$B$27=Ayarlar!$E$24,ISNUMBER(AE12)),IF(AD12="",Ayarlar!$B$10,AD12),0)+IF(AND(Ayarlar!$B$28=Ayarlar!$E$24,ISNUMBER(AI12)),IF(AH12="",Ayarlar!$B$11,AH12),0))*Ayarlar!$F$24,"") | AU12: =IF(COUNT(AQ12,AR12,AS12,AT12)<4,"",Ayarlar!$F$25+AQ12*Ayarlar!$G$21+AR12*Ayarlar!$G$22+AS12*Ayarlar!$G$23+AT12*Ayarlar!$G$24)
A13: 9 | G13: =IF(AND(D13="",E13=""),"",D13-IF(Ayarlar!$B$16>0,E13/Ayarlar!$B$16,0)) | K13: =IF(AND(H13="",I13=""),"",H13-IF(Ayarlar!$B$16>0,I13/Ayarlar!$B$16,0)) | O13: =IF(AND(L13="",M13=""),"",L13-IF(Ayarlar!$B$16>0,M13/Ayarlar!$B$16,0)) | S13: =IF(AND(P13="",Q13=""),"",P13-IF(Ayarlar!$B$16>0,Q13/Ayarlar!$B$16,0)) | W13: =IF(AND(T13="",U13=""),"",T13-IF(Ayarlar!$B$16>0,U13/Ayarlar!$B$16,0)) | AA13: =IF(AND(X13="",Y13=""),"",X13-IF(Ayarlar!$B$16>0,Y13/Ayarlar!$B$16,0)) | AE13: =IF(AND(AB13="",AC13=""),"",AB13-IF(Ayarlar!$B$16>0,AC13/Ayarlar!$B$16,0)) | AI13: =IF(AND(AF13="",AG13=""),"",AF13-IF(Ayarlar!$B$16>0,AG13/Ayarlar!$B$16,0)) | AJ13: =IF(COUNT(D13,E13,H13,I13,L13,M13,P13,Q13,T13,U13,X13,Y13,AB13,AC13,AF13,AG13)=0,"",D13+H13+L13+P13+T13+X13+AB13+AF13) | AK13: =IF(COUNT(D13,E13,H13,I13,L13,M13,P13,Q13,T13,U13,X13,Y13,AB13,AC13,AF13,AG13)=0,"",E13+I13+M13+Q13+U13+Y13+AC13+AG13) | AL13: =IF(COUNT(D13,E13,H13,I13,L13,M13,P13,Q13,T13,U13,X13,Y13,AB13,AC13,AF13,AG13)=0,"",IF(ISNUMBER(G13),IF(F13="",Ayarlar!$B$4,F13),0)+IF(ISNUMBER(K13),IF(J13="",Ayarlar!$B$5,J13),0)+IF(ISNUMBER(O13),IF(N13="",Ayarlar!$B$6,N13),0)+IF(ISNUMBER(S13),IF(R13="",Ayarlar!$B$7,R13),0)+IF(ISNUMBER(W13),IF(V13="",Ayarlar!$B$8,V13),0)+IF(ISNUMBER(AA13),IF(Z13="",Ayarlar!$B$9,Z13),0)+IF(ISNUMBER(AE13),IF(AD13="",Ayarlar!$B$10,AD13),0)+IF(ISNUMBER(AI13),IF(AH13="",Ayarlar!$B$11,AH13),0)) | AM13: =IF(COUNT(D13,E13,H13,I13,L13,M13,P13,Q13,T13,U13,X13,Y13,AB13,AC13,AF13,AG13)=0,"",AL13-AJ13-AK13) | AN13: =IF(COUNT(D13,E13,H13,I13,L13,M13,P13,Q13,T13,U13,X13,Y13,AB13,AC13,AF13,AG13)=0,"",SUM(G13,K13,O13,S13,W13,AA13,AE13,AI13)) | AO13: =IF(OR(COUNT(D13,E13,H13,I13,L13,M13,P13,Q13,T13,U13,X13,Y13,AB13,AC13,AF13,AG13)=0,N(AL13)=0),"",AN13/AL13) | AP13: =IF(OR(AO13="",AO12=""),"",AO13-AO12) | AQ13: =IFERROR((IF(Ayarlar!$B$21=Ayarlar!$E$21,N(G13),0)+IF(Ayarlar!$B$22=Ayarlar!$E$21,N(K13),0)+IF(Ayarlar!$B$23=Ayarlar!$E$21,N(O13),0)+IF(Ayarlar!$B$24=Ayarlar!$E$21,N(S13),0)+IF(Ayarlar!$B$25=Ayarlar!$E$21,N(W13),0)+IF(Ayarlar!$B$26=Ayarlar!$E$21,N(AA13),0)+IF(Ayarlar!$B$27=Ayarlar!$E$21,N(AE13),0)+IF(Ayarlar!$B$28=Ayarlar!$E$21,N(AI13),0))/(IF(AND(Ayarlar!$B$21=Ayarlar!$E$21,ISNUMBER(G13)),IF(F13="",Ayarlar!$B$4,F13),0)+IF(AND(Ayarlar!$B$22=Ayarlar!$E$21,ISNUMBER(K13)),IF(J13="",Ayarlar!$B$5,J13),0)+IF(AND(Ayarlar!$B$23=Ayarlar!$E$21,ISNUMBER(O13)),IF(N13="",Ayarlar!$B$6,N13),0)+IF(AND(Ayarlar!$B$24=Ayarlar!$E$21,ISNUMBER(S13)),IF(R13="",Ayarlar!$B$7,R13),0)+IF(AND(Ayarlar!$B$25=Ayarlar!$E$21,ISNUMBER(W13)),IF(V13="",Ayarlar!$B$8,V13),0)+IF(AND(Ayarlar!$B$26=Ayarlar!$E$21,ISNUMBER(AA13)),IF(Z13="",Ayarlar!$B$9,Z13),0)+IF(AND(Ayarlar!$B$27=Ayarlar!$E$21,ISNUMBER(AE13)),IF(AD13="",Ayarlar!$B$10,AD13),0)+IF(AND(Ayarlar!$B$28=Ayarlar!$E$21,ISNUMBER(AI13)),IF(AH13="",Ayarlar!$B$11,AH13),0))*Ayarlar!$F$21,"") | AR13: =IFERROR((IF(Ayarlar!$B$21=Ayarlar!$E$22,N(G13),0)+IF(Ayarlar!$B$22=Ayarlar!$E$22,N(K13),0)+IF(Ayarlar!$B$23=Ayarlar!$E$22,N(O13),0)+IF(Ayarlar!$B$24=Ayarlar!$E$22,N(S13),0)+IF(Ayarlar!$B$25=Ayarlar!$E$22,N(W13),0)+IF(Ayarlar!$B$26=Ayarlar!$E$22,N(AA13),0)+IF(Ayarlar!$B$27=Ayarlar!$E$22,N(AE13),0)+IF(Ayarlar!$B$28=Ayarlar!$E$22,N(AI13),0))/(IF(AND(Ayarlar!$B$21=Ayarlar!$E$22,ISNUMBER(G13)),IF(F13="",Ayarlar!$B$4,F13),0)+IF(AND(Ayarlar!$B$22=Ayarlar!$E$22,ISNUMBER(K13)),IF(J13="",Ayarlar!$B$5,J13),0)+IF(AND(Ayarlar!$B$23=Ayarlar!$E$22,ISNUMBER(O13)),IF(N13="",Ayarlar!$B$6,N13),0)+IF(AND(Ayarlar!$B$24=Ayarlar!$E$22,ISNUMBER(S13)),IF(R13="",Ayarlar!$B$7,R13),0)+IF(AND(Ayarlar!$B$25=Ayarlar!$E$22,ISNUMBER(W13)),IF(V13="",Ayarlar!$B$8,V13),0)+IF(AND(Ayarlar!$B$26=Ayarlar!$E$22,ISNUMBER(AA13)),IF(Z13="",Ayarlar!$B$9,Z13),0)+IF(AND(Ayarlar!$B$27=Ayarlar!$E$22,ISNUMBER(AE13)),IF(AD13="",Ayarlar!$B$10,AD13),0)+IF(AND(Ayarlar!$B$28=Ayarlar!$E$22,ISNUMBER(AI13)),IF(AH13="",Ayarlar!$B$11,AH13),0))*Ayarlar!$F$22,"") | AS13: =IFERROR((IF(Ayarlar!$B$21=Ayarlar!$E$23,N(G13),0)+IF(Ayarlar!$B$22=Ayarlar!$E$23,N(K13),0)+IF(Ayarlar!$B$23=Ayarlar!$E$23,N(O13),0)+IF(Ayarlar!$B$24=Ayarlar!$E$23,N(S13),0)+IF(Ayarlar!$B$25=Ayarlar!$E$23,N(W13),0)+IF(Ayarlar!$B$26=Ayarlar!$E$23,N(AA13),0)+IF(Ayarlar!$B$27=Ayarlar!$E$23,N(AE13),0)+IF(Ayarlar!$B$28=Ayarlar!$E$23,N(AI13),0))/(IF(AND(Ayarlar!$B$21=Ayarlar!$E$23,ISNUMBER(G13)),IF(F13="",Ayarlar!$B$4,F13),0)+IF(AND(Ayarlar!$B$22=Ayarlar!$E$23,ISNUMBER(K13)),IF(J13="",Ayarlar!$B$5,J13),0)+IF(AND(Ayarlar!$B$23=Ayarlar!$E$23,ISNUMBER(O13)),IF(N13="",Ayarlar!$B$6,N13),0)+IF(AND(Ayarlar!$B$24=Ayarlar!$E$23,ISNUMBER(S13)),IF(R13="",Ayarlar!$B$7,R13),0)+IF(AND(Ayarlar!$B$25=Ayarlar!$E$23,ISNUMBER(W13)),IF(V13="",Ayarlar!$B$8,V13),0)+IF(AND(Ayarlar!$B$26=Ayarlar!$E$23,ISNUMBER(AA13)),IF(Z13="",Ayarlar!$B$9,Z13),0)+IF(AND(Ayarlar!$B$27=Ayarlar!$E$23,ISNUMBER(AE13)),IF(AD13="",Ayarlar!$B$10,AD13),0)+IF(AND(Ayarlar!$B$28=Ayarlar!$E$23,ISNUMBER(AI13)),IF(AH13="",Ayarlar!$B$11,AH13),0))*Ayarlar!$F$23,"") | AT13: =IFERROR((IF(Ayarlar!$B$21=Ayarlar!$E$24,N(G13),0)+IF(Ayarlar!$B$22=Ayarlar!$E$24,N(K13),0)+IF(Ayarlar!$B$23=Ayarlar!$E$24,N(O13),0)+IF(Ayarlar!$B$24=Ayarlar!$E$24,N(S13),0)+IF(Ayarlar!$B$25=Ayarlar!$E$24,N(W13),0)+IF(Ayarlar!$B$26=Ayarlar!$E$24,N(AA13),0)+IF(Ayarlar!$B$27=Ayarlar!$E$24,N(AE13),0)+IF(Ayarlar!$B$28=Ayarlar!$E$24,N(AI13),0))/(IF(AND(Ayarlar!$B$21=Ayarlar!$E$24,ISNUMBER(G13)),IF(F13="",Ayarlar!$B$4,F13),0)+IF(AND(Ayarlar!$B$22=Ayarlar!$E$24,ISNUMBER(K13)),IF(J13="",Ayarlar!$B$5,J13),0)+IF(AND(Ayarlar!$B$23=Ayarlar!$E$24,ISNUMBER(O13)),IF(N13="",Ayarlar!$B$6,N13),0)+IF(AND(Ayarlar!$B$24=Ayarlar!$E$24,ISNUMBER(S13)),IF(R13="",Ayarlar!$B$7,R13),0)+IF(AND(Ayarlar!$B$25=Ayarlar!$E$24,ISNUMBER(W13)),IF(V13="",Ayarlar!$B$8,V13),0)+IF(AND(Ayarlar!$B$26=Ayarlar!$E$24,ISNUMBER(AA13)),IF(Z13="",Ayarlar!$B$9,Z13),0)+IF(AND(Ayarlar!$B$27=Ayarlar!$E$24,ISNUMBER(AE13)),IF(AD13="",Ayarlar!$B$10,AD13),0)+IF(AND(Ayarlar!$B$28=Ayarlar!$E$24,ISNUMBER(AI13)),IF(AH13="",Ayarlar!$B$11,AH13),0))*Ayarlar!$F$24,"") | AU13: =IF(COUNT(AQ13,AR13,AS13,AT13)<4,"",Ayarlar!$F$25+AQ13*Ayarlar!$G$21+AR13*Ayarlar!$G$22+AS13*Ayarlar!$G$23+AT13*Ayarlar!$G$24)
